INFO:waitress:Serving on http://0.0.0.0:8000
ERROR:django.request:Internal Server Error: /
Traceback (most recent call last):
  File "C:\Users\USER\AppData\Local\Programs\Python\Python313\Lib\site-packages\django\db\backends\utils.py", line 105, in _execute
    return self.cursor.execute(sql, params)
           ~~~~~~~~~~~~~~~~~~~^^^^^^^^^^^^^
  File "C:\Users\USER\AppData\Local\Programs\Python\Python313\Lib\site-packages\django\db\backends\sqlite3\base.py", line 354, in execute
    return super().execute(query, params)
           ~~~~~~~~~~~~~~~^^^^^^^^^^^^^^^
sqlite3.OperationalError: no such column: inventory_product.vat_rate_id

The above exception was the direct cause of the following exception:

Traceback (most recent call last):
  File "C:\Users\USER\AppData\Local\Programs\Python\Python313\Lib\site-packages\django\core\handlers\exception.py", line 55, in inner
    response = get_response(request)
  File "C:\Users\USER\AppData\Local\Programs\Python\Python313\Lib\site-packages\django\core\handlers\base.py", line 220, in _get_response
    response = response.render()
  File "C:\Users\USER\AppData\Local\Programs\Python\Python313\Lib\site-packages\django\template\response.py", line 114, in render
    self.content = self.rendered_content
                   ^^^^^^^^^^^^^^^^^^^^^
  File "C:\Users\USER\AppData\Local\Programs\Python\Python313\Lib\site-packages\django\template\response.py", line 92, in rendered_content
    return template.render(context, self._request)
           ~~~~~~~~~~~~~~~^^^^^^^^^^^^^^^^^^^^^^^^
  File "C:\Users\USER\AppData\Local\Programs\Python\Python313\Lib\site-packages\django\template\backends\django.py", line 107, in render
    return self.template.render(context)
           ~~~~~~~~~~~~~~~~~~~~^^^^^^^^^
  File "C:\Users\USER\AppData\Local\Programs\Python\Python313\Lib\site-packages\django\template\base.py", line 171, in render
    return self._render(context)
           ~~~~~~~~~~~~^^^^^^^^^
  File "C:\Users\USER\AppData\Local\Programs\Python\Python313\Lib\site-packages\django\template\base.py", line 163, in _render
    return self.nodelist.render(context)
           ~~~~~~~~~~~~~~~~~~~~^^^^^^^^^
  File "C:\Users\USER\AppData\Local\Programs\Python\Python313\Lib\site-packages\django\template\base.py", line 1008, in render
    return SafeString("".join([node.render_annotated(context) for node in self]))
                               ~~~~~~~~~~~~~~~~~~~~~^^^^^^^^^
  File "C:\Users\USER\AppData\Local\Programs\Python\Python313\Lib\site-packages\django\template\base.py", line 969, in render_annotated
    return self.render(context)
           ~~~~~~~~~~~^^^^^^^^^
  File "C:\Users\USER\AppData\Local\Programs\Python\Python313\Lib\site-packages\django\template\loader_tags.py", line 159, in render
    return compiled_parent._render(context)
           ~~~~~~~~~~~~~~~~~~~~~~~^^^^^^^^^
  File "C:\Users\USER\AppData\Local\Programs\Python\Python313\Lib\site-packages\django\template\base.py", line 163, in _render
    return self.nodelist.render(context)
           ~~~~~~~~~~~~~~~~~~~~^^^^^^^^^
  File "C:\Users\USER\AppData\Local\Programs\Python\Python313\Lib\site-packages\django\template\base.py", line 1008, in render
    return SafeString("".join([node.render_annotated(context) for node in self]))
                               ~~~~~~~~~~~~~~~~~~~~~^^^^^^^^^
  File "C:\Users\USER\AppData\Local\Programs\Python\Python313\Lib\site-packages\django\template\base.py", line 969, in render_annotated
    return self.render(context)
           ~~~~~~~~~~~^^^^^^^^^
  File "C:\Users\USER\AppData\Local\Programs\Python\Python313\Lib\site-packages\django\template\defaulttags.py", line 327, in render
    return nodelist.render(context)
           ~~~~~~~~~~~~~~~^^^^^^^^^
  File "C:\Users\USER\AppData\Local\Programs\Python\Python313\Lib\site-packages\django\template\base.py", line 1008, in render
    return SafeString("".join([node.render_annotated(context) for node in self]))
                               ~~~~~~~~~~~~~~~~~~~~~^^^^^^^^^
  File "C:\Users\USER\AppData\Local\Programs\Python\Python313\Lib\site-packages\django\template\base.py", line 969, in render_annotated
    return self.render(context)
           ~~~~~~~~~~~^^^^^^^^^
  File "C:\Users\USER\AppData\Local\Programs\Python\Python313\Lib\site-packages\django\template\loader_tags.py", line 65, in render
    result = block.nodelist.render(context)
  File "C:\Users\USER\AppData\Local\Programs\Python\Python313\Lib\site-packages\django\template\base.py", line 1008, in render
    return SafeString("".join([node.render_annotated(context) for node in self]))
                               ~~~~~~~~~~~~~~~~~~~~~^^^^^^^^^
  File "C:\Users\USER\AppData\Local\Programs\Python\Python313\Lib\site-packages\django\template\base.py", line 969, in render_annotated
    return self.render(context)
           ~~~~~~~~~~~^^^^^^^^^
  File "C:\Users\USER\AppData\Local\Programs\Python\Python313\Lib\site-packages\django\template\defaulttags.py", line 199, in render
    len_values = len(values)
  File "C:\Users\USER\AppData\Local\Programs\Python\Python313\Lib\site-packages\django\db\models\query.py", line 382, in __len__
    self._fetch_all()
    ~~~~~~~~~~~~~~~^^
  File "C:\Users\USER\AppData\Local\Programs\Python\Python313\Lib\site-packages\django\db\models\query.py", line 1928, in _fetch_all
    self._result_cache = list(self._iterable_class(self))
                         ~~~~^^^^^^^^^^^^^^^^^^^^^^^^^^^^
  File "C:\Users\USER\AppData\Local\Programs\Python\Python313\Lib\site-packages\django\db\models\query.py", line 91, in __iter__
    results = compiler.execute_sql(
        chunked_fetch=self.chunked_fetch, chunk_size=self.chunk_size
    )
  File "C:\Users\USER\AppData\Local\Programs\Python\Python313\Lib\site-packages\django\db\models\sql\compiler.py", line 1574, in execute_sql
    cursor.execute(sql, params)
    ~~~~~~~~~~~~~~^^^^^^^^^^^^^
  File "C:\Users\USER\AppData\Local\Programs\Python\Python313\Lib\site-packages\django\db\backends\utils.py", line 79, in execute
    return self._execute_with_wrappers(
           ~~~~~~~~~~~~~~~~~~~~~~~~~~~^
        sql, params, many=False, executor=self._execute
        ^^^^^^^^^^^^^^^^^^^^^^^^^^^^^^^^^^^^^^^^^^^^^^^
    )
    ^
  File "C:\Users\USER\AppData\Local\Programs\Python\Python313\Lib\site-packages\django\db\backends\utils.py", line 92, in _execute_with_wrappers
    return executor(sql, params, many, context)
  File "C:\Users\USER\AppData\Local\Programs\Python\Python313\Lib\site-packages\django\db\backends\utils.py", line 100, in _execute
    with self.db.wrap_database_errors:
         ^^^^^^^^^^^^^^^^^^^^^^^^^^^^
  File "C:\Users\USER\AppData\Local\Programs\Python\Python313\Lib\site-packages\django\db\utils.py", line 91, in __exit__
    raise dj_exc_value.with_traceback(traceback) from exc_value
  File "C:\Users\USER\AppData\Local\Programs\Python\Python313\Lib\site-packages\django\db\backends\utils.py", line 105, in _execute
    return self.cursor.execute(sql, params)
           ~~~~~~~~~~~~~~~~~~~^^^^^^^^^^^^^
  File "C:\Users\USER\AppData\Local\Programs\Python\Python313\Lib\site-packages\django\db\backends\sqlite3\base.py", line 354, in execute
    return super().execute(query, params)
           ~~~~~~~~~~~~~~~^^^^^^^^^^^^^^^
django.db.utils.OperationalError: no such column: inventory_product.vat_rate_id
INFO:waitress:Serving on http://0.0.0.0:8000
ERROR:django.request:Internal Server Error: /service/234/
Traceback (most recent call last):
  File "C:\Users\USER\AppData\Local\Programs\Python\Python313\Lib\site-packages\django\template\base.py", line 883, in _resolve_lookup
    current = current[bit]
              ~~~~~~~^^^^^
TypeError: 'NoneType' object is not subscriptable

During handling of the above exception, another exception occurred:

Traceback (most recent call last):
  File "C:\Users\USER\AppData\Local\Programs\Python\Python313\Lib\site-packages\django\template\base.py", line 893, in _resolve_lookup
    current = getattr(current, bit)
AttributeError: 'NoneType' object has no attribute 'username'

During handling of the above exception, another exception occurred:

Traceback (most recent call last):
  File "C:\Users\USER\AppData\Local\Programs\Python\Python313\Lib\site-packages\django\template\base.py", line 899, in _resolve_lookup
    current = current[int(bit)]
                      ~~~^^^^^
ValueError: invalid literal for int() with base 10: 'username'

During handling of the above exception, another exception occurred:

Traceback (most recent call last):
  File "C:\Users\USER\AppData\Local\Programs\Python\Python313\Lib\site-packages\django\core\handlers\exception.py", line 55, in inner
    response = get_response(request)
  File "C:\Users\USER\AppData\Local\Programs\Python\Python313\Lib\site-packages\django\core\handlers\base.py", line 220, in _get_response
    response = response.render()
  File "C:\Users\USER\AppData\Local\Programs\Python\Python313\Lib\site-packages\django\template\response.py", line 114, in render
    self.content = self.rendered_content
                   ^^^^^^^^^^^^^^^^^^^^^
  File "C:\Users\USER\AppData\Local\Programs\Python\Python313\Lib\site-packages\django\template\response.py", line 92, in rendered_content
    return template.render(context, self._request)
           ~~~~~~~~~~~~~~~^^^^^^^^^^^^^^^^^^^^^^^^
  File "C:\Users\USER\AppData\Local\Programs\Python\Python313\Lib\site-packages\django\template\backends\django.py", line 107, in render
    return self.template.render(context)
           ~~~~~~~~~~~~~~~~~~~~^^^^^^^^^
  File "C:\Users\USER\AppData\Local\Programs\Python\Python313\Lib\site-packages\django\template\base.py", line 171, in render
    return self._render(context)
           ~~~~~~~~~~~~^^^^^^^^^
  File "C:\Users\USER\AppData\Local\Programs\Python\Python313\Lib\site-packages\django\template\base.py", line 163, in _render
    return self.nodelist.render(context)
           ~~~~~~~~~~~~~~~~~~~~^^^^^^^^^
  File "C:\Users\USER\AppData\Local\Programs\Python\Python313\Lib\site-packages\django\template\base.py", line 1008, in render
    return SafeString("".join([node.render_annotated(context) for node in self]))
                               ~~~~~~~~~~~~~~~~~~~~~^^^^^^^^^
  File "C:\Users\USER\AppData\Local\Programs\Python\Python313\Lib\site-packages\django\template\base.py", line 969, in render_annotated
    return self.render(context)
           ~~~~~~~~~~~^^^^^^^^^
  File "C:\Users\USER\AppData\Local\Programs\Python\Python313\Lib\site-packages\django\template\loader_tags.py", line 159, in render
    return compiled_parent._render(context)
           ~~~~~~~~~~~~~~~~~~~~~~~^^^^^^^^^
  File "C:\Users\USER\AppData\Local\Programs\Python\Python313\Lib\site-packages\django\template\base.py", line 163, in _render
    return self.nodelist.render(context)
           ~~~~~~~~~~~~~~~~~~~~^^^^^^^^^
  File "C:\Users\USER\AppData\Local\Programs\Python\Python313\Lib\site-packages\django\template\base.py", line 1008, in render
    return SafeString("".join([node.render_annotated(context) for node in self]))
                               ~~~~~~~~~~~~~~~~~~~~~^^^^^^^^^
  File "C:\Users\USER\AppData\Local\Programs\Python\Python313\Lib\site-packages\django\template\base.py", line 969, in render_annotated
    return self.render(context)
           ~~~~~~~~~~~^^^^^^^^^
  File "C:\Users\USER\AppData\Local\Programs\Python\Python313\Lib\site-packages\django\template\defaulttags.py", line 327, in render
    return nodelist.render(context)
           ~~~~~~~~~~~~~~~^^^^^^^^^
  File "C:\Users\USER\AppData\Local\Programs\Python\Python313\Lib\site-packages\django\template\base.py", line 1008, in render
    return SafeString("".join([node.render_annotated(context) for node in self]))
                               ~~~~~~~~~~~~~~~~~~~~~^^^^^^^^^
  File "C:\Users\USER\AppData\Local\Programs\Python\Python313\Lib\site-packages\django\template\base.py", line 969, in render_annotated
    return self.render(context)
           ~~~~~~~~~~~^^^^^^^^^
  File "C:\Users\USER\AppData\Local\Programs\Python\Python313\Lib\site-packages\django\template\loader_tags.py", line 65, in render
    result = block.nodelist.render(context)
  File "C:\Users\USER\AppData\Local\Programs\Python\Python313\Lib\site-packages\django\template\base.py", line 1008, in render
    return SafeString("".join([node.render_annotated(context) for node in self]))
                               ~~~~~~~~~~~~~~~~~~~~~^^^^^^^^^
  File "C:\Users\USER\AppData\Local\Programs\Python\Python313\Lib\site-packages\django\template\base.py", line 969, in render_annotated
    return self.render(context)
           ~~~~~~~~~~~^^^^^^^^^
  File "C:\Users\USER\AppData\Local\Programs\Python\Python313\Lib\site-packages\django\template\base.py", line 1067, in render
    output = self.filter_expression.resolve(context)
  File "C:\Users\USER\AppData\Local\Programs\Python\Python313\Lib\site-packages\django\template\base.py", line 739, in resolve
    arg_vals.append(arg.resolve(context))
                    ~~~~~~~~~~~^^^^^^^^^
  File "C:\Users\USER\AppData\Local\Programs\Python\Python313\Lib\site-packages\django\template\base.py", line 850, in resolve
    value = self._resolve_lookup(context)
  File "C:\Users\USER\AppData\Local\Programs\Python\Python313\Lib\site-packages\django\template\base.py", line 906, in _resolve_lookup
    raise VariableDoesNotExist(
    ^^^^^^^^^^^^^^^^^^^^^^^^^^^
    ...<2 lines>...
    )  # missing attribute
    ^
django.template.base.VariableDoesNotExist: Failed lookup for key [username] in None
ERROR:django.request:Internal Server Error: /service/234/
Traceback (most recent call last):
  File "C:\Users\USER\AppData\Local\Programs\Python\Python313\Lib\site-packages\django\template\base.py", line 883, in _resolve_lookup
    current = current[bit]
              ~~~~~~~^^^^^
TypeError: 'NoneType' object is not subscriptable

During handling of the above exception, another exception occurred:

Traceback (most recent call last):
  File "C:\Users\USER\AppData\Local\Programs\Python\Python313\Lib\site-packages\django\template\base.py", line 893, in _resolve_lookup
    current = getattr(current, bit)
AttributeError: 'NoneType' object has no attribute 'username'

During handling of the above exception, another exception occurred:

Traceback (most recent call last):
  File "C:\Users\USER\AppData\Local\Programs\Python\Python313\Lib\site-packages\django\template\base.py", line 899, in _resolve_lookup
    current = current[int(bit)]
                      ~~~^^^^^
ValueError: invalid literal for int() with base 10: 'username'

During handling of the above exception, another exception occurred:

Traceback (most recent call last):
  File "C:\Users\USER\AppData\Local\Programs\Python\Python313\Lib\site-packages\django\core\handlers\exception.py", line 55, in inner
    response = get_response(request)
  File "C:\Users\USER\AppData\Local\Programs\Python\Python313\Lib\site-packages\django\core\handlers\base.py", line 220, in _get_response
    response = response.render()
  File "C:\Users\USER\AppData\Local\Programs\Python\Python313\Lib\site-packages\django\template\response.py", line 114, in render
    self.content = self.rendered_content
                   ^^^^^^^^^^^^^^^^^^^^^
  File "C:\Users\USER\AppData\Local\Programs\Python\Python313\Lib\site-packages\django\template\response.py", line 92, in rendered_content
    return template.render(context, self._request)
           ~~~~~~~~~~~~~~~^^^^^^^^^^^^^^^^^^^^^^^^
  File "C:\Users\USER\AppData\Local\Programs\Python\Python313\Lib\site-packages\django\template\backends\django.py", line 107, in render
    return self.template.render(context)
           ~~~~~~~~~~~~~~~~~~~~^^^^^^^^^
  File "C:\Users\USER\AppData\Local\Programs\Python\Python313\Lib\site-packages\django\template\base.py", line 171, in render
    return self._render(context)
           ~~~~~~~~~~~~^^^^^^^^^
  File "C:\Users\USER\AppData\Local\Programs\Python\Python313\Lib\site-packages\django\template\base.py", line 163, in _render
    return self.nodelist.render(context)
           ~~~~~~~~~~~~~~~~~~~~^^^^^^^^^
  File "C:\Users\USER\AppData\Local\Programs\Python\Python313\Lib\site-packages\django\template\base.py", line 1008, in render
    return SafeString("".join([node.render_annotated(context) for node in self]))
                               ~~~~~~~~~~~~~~~~~~~~~^^^^^^^^^
  File "C:\Users\USER\AppData\Local\Programs\Python\Python313\Lib\site-packages\django\template\base.py", line 969, in render_annotated
    return self.render(context)
           ~~~~~~~~~~~^^^^^^^^^
  File "C:\Users\USER\AppData\Local\Programs\Python\Python313\Lib\site-packages\django\template\loader_tags.py", line 159, in render
    return compiled_parent._render(context)
           ~~~~~~~~~~~~~~~~~~~~~~~^^^^^^^^^
  File "C:\Users\USER\AppData\Local\Programs\Python\Python313\Lib\site-packages\django\template\base.py", line 163, in _render
    return self.nodelist.render(context)
           ~~~~~~~~~~~~~~~~~~~~^^^^^^^^^
  File "C:\Users\USER\AppData\Local\Programs\Python\Python313\Lib\site-packages\django\template\base.py", line 1008, in render
    return SafeString("".join([node.render_annotated(context) for node in self]))
                               ~~~~~~~~~~~~~~~~~~~~~^^^^^^^^^
  File "C:\Users\USER\AppData\Local\Programs\Python\Python313\Lib\site-packages\django\template\base.py", line 969, in render_annotated
    return self.render(context)
           ~~~~~~~~~~~^^^^^^^^^
  File "C:\Users\USER\AppData\Local\Programs\Python\Python313\Lib\site-packages\django\template\defaulttags.py", line 327, in render
    return nodelist.render(context)
           ~~~~~~~~~~~~~~~^^^^^^^^^
  File "C:\Users\USER\AppData\Local\Programs\Python\Python313\Lib\site-packages\django\template\base.py", line 1008, in render
    return SafeString("".join([node.render_annotated(context) for node in self]))
                               ~~~~~~~~~~~~~~~~~~~~~^^^^^^^^^
  File "C:\Users\USER\AppData\Local\Programs\Python\Python313\Lib\site-packages\django\template\base.py", line 969, in render_annotated
    return self.render(context)
           ~~~~~~~~~~~^^^^^^^^^
  File "C:\Users\USER\AppData\Local\Programs\Python\Python313\Lib\site-packages\django\template\loader_tags.py", line 65, in render
    result = block.nodelist.render(context)
  File "C:\Users\USER\AppData\Local\Programs\Python\Python313\Lib\site-packages\django\template\base.py", line 1008, in render
    return SafeString("".join([node.render_annotated(context) for node in self]))
                               ~~~~~~~~~~~~~~~~~~~~~^^^^^^^^^
  File "C:\Users\USER\AppData\Local\Programs\Python\Python313\Lib\site-packages\django\template\base.py", line 969, in render_annotated
    return self.render(context)
           ~~~~~~~~~~~^^^^^^^^^
  File "C:\Users\USER\AppData\Local\Programs\Python\Python313\Lib\site-packages\django\template\base.py", line 1067, in render
    output = self.filter_expression.resolve(context)
  File "C:\Users\USER\AppData\Local\Programs\Python\Python313\Lib\site-packages\django\template\base.py", line 739, in resolve
    arg_vals.append(arg.resolve(context))
                    ~~~~~~~~~~~^^^^^^^^^
  File "C:\Users\USER\AppData\Local\Programs\Python\Python313\Lib\site-packages\django\template\base.py", line 850, in resolve
    value = self._resolve_lookup(context)
  File "C:\Users\USER\AppData\Local\Programs\Python\Python313\Lib\site-packages\django\template\base.py", line 906, in _resolve_lookup
    raise VariableDoesNotExist(
    ^^^^^^^^^^^^^^^^^^^^^^^^^^^
    ...<2 lines>...
    )  # missing attribute
    ^
django.template.base.VariableDoesNotExist: Failed lookup for key [username] in None
ERROR:django.request:Internal Server Error: /service/234/
Traceback (most recent call last):
  File "C:\Users\USER\AppData\Local\Programs\Python\Python313\Lib\site-packages\django\template\base.py", line 883, in _resolve_lookup
    current = current[bit]
              ~~~~~~~^^^^^
TypeError: 'NoneType' object is not subscriptable

During handling of the above exception, another exception occurred:

Traceback (most recent call last):
  File "C:\Users\USER\AppData\Local\Programs\Python\Python313\Lib\site-packages\django\template\base.py", line 893, in _resolve_lookup
    current = getattr(current, bit)
AttributeError: 'NoneType' object has no attribute 'username'

During handling of the above exception, another exception occurred:

Traceback (most recent call last):
  File "C:\Users\USER\AppData\Local\Programs\Python\Python313\Lib\site-packages\django\template\base.py", line 899, in _resolve_lookup
    current = current[int(bit)]
                      ~~~^^^^^
ValueError: invalid literal for int() with base 10: 'username'

During handling of the above exception, another exception occurred:

Traceback (most recent call last):
  File "C:\Users\USER\AppData\Local\Programs\Python\Python313\Lib\site-packages\django\core\handlers\exception.py", line 55, in inner
    response = get_response(request)
  File "C:\Users\USER\AppData\Local\Programs\Python\Python313\Lib\site-packages\django\core\handlers\base.py", line 220, in _get_response
    response = response.render()
  File "C:\Users\USER\AppData\Local\Programs\Python\Python313\Lib\site-packages\django\template\response.py", line 114, in render
    self.content = self.rendered_content
                   ^^^^^^^^^^^^^^^^^^^^^
  File "C:\Users\USER\AppData\Local\Programs\Python\Python313\Lib\site-packages\django\template\response.py", line 92, in rendered_content
    return template.render(context, self._request)
           ~~~~~~~~~~~~~~~^^^^^^^^^^^^^^^^^^^^^^^^
  File "C:\Users\USER\AppData\Local\Programs\Python\Python313\Lib\site-packages\django\template\backends\django.py", line 107, in render
    return self.template.render(context)
           ~~~~~~~~~~~~~~~~~~~~^^^^^^^^^
  File "C:\Users\USER\AppData\Local\Programs\Python\Python313\Lib\site-packages\django\template\base.py", line 171, in render
    return self._render(context)
           ~~~~~~~~~~~~^^^^^^^^^
  File "C:\Users\USER\AppData\Local\Programs\Python\Python313\Lib\site-packages\django\template\base.py", line 163, in _render
    return self.nodelist.render(context)
           ~~~~~~~~~~~~~~~~~~~~^^^^^^^^^
  File "C:\Users\USER\AppData\Local\Programs\Python\Python313\Lib\site-packages\django\template\base.py", line 1008, in render
    return SafeString("".join([node.render_annotated(context) for node in self]))
                               ~~~~~~~~~~~~~~~~~~~~~^^^^^^^^^
  File "C:\Users\USER\AppData\Local\Programs\Python\Python313\Lib\site-packages\django\template\base.py", line 969, in render_annotated
    return self.render(context)
           ~~~~~~~~~~~^^^^^^^^^
  File "C:\Users\USER\AppData\Local\Programs\Python\Python313\Lib\site-packages\django\template\loader_tags.py", line 159, in render
    return compiled_parent._render(context)
           ~~~~~~~~~~~~~~~~~~~~~~~^^^^^^^^^
  File "C:\Users\USER\AppData\Local\Programs\Python\Python313\Lib\site-packages\django\template\base.py", line 163, in _render
    return self.nodelist.render(context)
           ~~~~~~~~~~~~~~~~~~~~^^^^^^^^^
  File "C:\Users\USER\AppData\Local\Programs\Python\Python313\Lib\site-packages\django\template\base.py", line 1008, in render
    return SafeString("".join([node.render_annotated(context) for node in self]))
                               ~~~~~~~~~~~~~~~~~~~~~^^^^^^^^^
  File "C:\Users\USER\AppData\Local\Programs\Python\Python313\Lib\site-packages\django\template\base.py", line 969, in render_annotated
    return self.render(context)
           ~~~~~~~~~~~^^^^^^^^^
  File "C:\Users\USER\AppData\Local\Programs\Python\Python313\Lib\site-packages\django\template\defaulttags.py", line 327, in render
    return nodelist.render(context)
           ~~~~~~~~~~~~~~~^^^^^^^^^
  File "C:\Users\USER\AppData\Local\Programs\Python\Python313\Lib\site-packages\django\template\base.py", line 1008, in render
    return SafeString("".join([node.render_annotated(context) for node in self]))
                               ~~~~~~~~~~~~~~~~~~~~~^^^^^^^^^
  File "C:\Users\USER\AppData\Local\Programs\Python\Python313\Lib\site-packages\django\template\base.py", line 969, in render_annotated
    return self.render(context)
           ~~~~~~~~~~~^^^^^^^^^
  File "C:\Users\USER\AppData\Local\Programs\Python\Python313\Lib\site-packages\django\template\loader_tags.py", line 65, in render
    result = block.nodelist.render(context)
  File "C:\Users\USER\AppData\Local\Programs\Python\Python313\Lib\site-packages\django\template\base.py", line 1008, in render
    return SafeString("".join([node.render_annotated(context) for node in self]))
                               ~~~~~~~~~~~~~~~~~~~~~^^^^^^^^^
  File "C:\Users\USER\AppData\Local\Programs\Python\Python313\Lib\site-packages\django\template\base.py", line 969, in render_annotated
    return self.render(context)
           ~~~~~~~~~~~^^^^^^^^^
  File "C:\Users\USER\AppData\Local\Programs\Python\Python313\Lib\site-packages\django\template\base.py", line 1067, in render
    output = self.filter_expression.resolve(context)
  File "C:\Users\USER\AppData\Local\Programs\Python\Python313\Lib\site-packages\django\template\base.py", line 739, in resolve
    arg_vals.append(arg.resolve(context))
                    ~~~~~~~~~~~^^^^^^^^^
  File "C:\Users\USER\AppData\Local\Programs\Python\Python313\Lib\site-packages\django\template\base.py", line 850, in resolve
    value = self._resolve_lookup(context)
  File "C:\Users\USER\AppData\Local\Programs\Python\Python313\Lib\site-packages\django\template\base.py", line 906, in _resolve_lookup
    raise VariableDoesNotExist(
    ^^^^^^^^^^^^^^^^^^^^^^^^^^^
    ...<2 lines>...
    )  # missing attribute
    ^
django.template.base.VariableDoesNotExist: Failed lookup for key [username] in None
ERROR:django.request:Internal Server Error: /service/234/
Traceback (most recent call last):
  File "C:\Users\USER\AppData\Local\Programs\Python\Python313\Lib\site-packages\django\template\base.py", line 883, in _resolve_lookup
    current = current[bit]
              ~~~~~~~^^^^^
TypeError: 'NoneType' object is not subscriptable

During handling of the above exception, another exception occurred:

Traceback (most recent call last):
  File "C:\Users\USER\AppData\Local\Programs\Python\Python313\Lib\site-packages\django\template\base.py", line 893, in _resolve_lookup
    current = getattr(current, bit)
AttributeError: 'NoneType' object has no attribute 'username'

During handling of the above exception, another exception occurred:

Traceback (most recent call last):
  File "C:\Users\USER\AppData\Local\Programs\Python\Python313\Lib\site-packages\django\template\base.py", line 899, in _resolve_lookup
    current = current[int(bit)]
                      ~~~^^^^^
ValueError: invalid literal for int() with base 10: 'username'

During handling of the above exception, another exception occurred:

Traceback (most recent call last):
  File "C:\Users\USER\AppData\Local\Programs\Python\Python313\Lib\site-packages\django\core\handlers\exception.py", line 55, in inner
    response = get_response(request)
  File "C:\Users\USER\AppData\Local\Programs\Python\Python313\Lib\site-packages\django\core\handlers\base.py", line 220, in _get_response
    response = response.render()
  File "C:\Users\USER\AppData\Local\Programs\Python\Python313\Lib\site-packages\django\template\response.py", line 114, in render
    self.content = self.rendered_content
                   ^^^^^^^^^^^^^^^^^^^^^
  File "C:\Users\USER\AppData\Local\Programs\Python\Python313\Lib\site-packages\django\template\response.py", line 92, in rendered_content
    return template.render(context, self._request)
           ~~~~~~~~~~~~~~~^^^^^^^^^^^^^^^^^^^^^^^^
  File "C:\Users\USER\AppData\Local\Programs\Python\Python313\Lib\site-packages\django\template\backends\django.py", line 107, in render
    return self.template.render(context)
           ~~~~~~~~~~~~~~~~~~~~^^^^^^^^^
  File "C:\Users\USER\AppData\Local\Programs\Python\Python313\Lib\site-packages\django\template\base.py", line 171, in render
    return self._render(context)
           ~~~~~~~~~~~~^^^^^^^^^
  File "C:\Users\USER\AppData\Local\Programs\Python\Python313\Lib\site-packages\django\template\base.py", line 163, in _render
    return self.nodelist.render(context)
           ~~~~~~~~~~~~~~~~~~~~^^^^^^^^^
  File "C:\Users\USER\AppData\Local\Programs\Python\Python313\Lib\site-packages\django\template\base.py", line 1008, in render
    return SafeString("".join([node.render_annotated(context) for node in self]))
                               ~~~~~~~~~~~~~~~~~~~~~^^^^^^^^^
  File "C:\Users\USER\AppData\Local\Programs\Python\Python313\Lib\site-packages\django\template\base.py", line 969, in render_annotated
    return self.render(context)
           ~~~~~~~~~~~^^^^^^^^^
  File "C:\Users\USER\AppData\Local\Programs\Python\Python313\Lib\site-packages\django\template\loader_tags.py", line 159, in render
    return compiled_parent._render(context)
           ~~~~~~~~~~~~~~~~~~~~~~~^^^^^^^^^
  File "C:\Users\USER\AppData\Local\Programs\Python\Python313\Lib\site-packages\django\template\base.py", line 163, in _render
    return self.nodelist.render(context)
           ~~~~~~~~~~~~~~~~~~~~^^^^^^^^^
  File "C:\Users\USER\AppData\Local\Programs\Python\Python313\Lib\site-packages\django\template\base.py", line 1008, in render
    return SafeString("".join([node.render_annotated(context) for node in self]))
                               ~~~~~~~~~~~~~~~~~~~~~^^^^^^^^^
  File "C:\Users\USER\AppData\Local\Programs\Python\Python313\Lib\site-packages\django\template\base.py", line 969, in render_annotated
    return self.render(context)
           ~~~~~~~~~~~^^^^^^^^^
  File "C:\Users\USER\AppData\Local\Programs\Python\Python313\Lib\site-packages\django\template\defaulttags.py", line 327, in render
    return nodelist.render(context)
           ~~~~~~~~~~~~~~~^^^^^^^^^
  File "C:\Users\USER\AppData\Local\Programs\Python\Python313\Lib\site-packages\django\template\base.py", line 1008, in render
    return SafeString("".join([node.render_annotated(context) for node in self]))
                               ~~~~~~~~~~~~~~~~~~~~~^^^^^^^^^
  File "C:\Users\USER\AppData\Local\Programs\Python\Python313\Lib\site-packages\django\template\base.py", line 969, in render_annotated
    return self.render(context)
           ~~~~~~~~~~~^^^^^^^^^
  File "C:\Users\USER\AppData\Local\Programs\Python\Python313\Lib\site-packages\django\template\loader_tags.py", line 65, in render
    result = block.nodelist.render(context)
  File "C:\Users\USER\AppData\Local\Programs\Python\Python313\Lib\site-packages\django\template\base.py", line 1008, in render
    return SafeString("".join([node.render_annotated(context) for node in self]))
                               ~~~~~~~~~~~~~~~~~~~~~^^^^^^^^^
  File "C:\Users\USER\AppData\Local\Programs\Python\Python313\Lib\site-packages\django\template\base.py", line 969, in render_annotated
    return self.render(context)
           ~~~~~~~~~~~^^^^^^^^^
  File "C:\Users\USER\AppData\Local\Programs\Python\Python313\Lib\site-packages\django\template\base.py", line 1067, in render
    output = self.filter_expression.resolve(context)
  File "C:\Users\USER\AppData\Local\Programs\Python\Python313\Lib\site-packages\django\template\base.py", line 739, in resolve
    arg_vals.append(arg.resolve(context))
                    ~~~~~~~~~~~^^^^^^^^^
  File "C:\Users\USER\AppData\Local\Programs\Python\Python313\Lib\site-packages\django\template\base.py", line 850, in resolve
    value = self._resolve_lookup(context)
  File "C:\Users\USER\AppData\Local\Programs\Python\Python313\Lib\site-packages\django\template\base.py", line 906, in _resolve_lookup
    raise VariableDoesNotExist(
    ^^^^^^^^^^^^^^^^^^^^^^^^^^^
    ...<2 lines>...
    )  # missing attribute
    ^
django.template.base.VariableDoesNotExist: Failed lookup for key [username] in None
ERROR:django.request:Internal Server Error: /service/234/
Traceback (most recent call last):
  File "C:\Users\USER\AppData\Local\Programs\Python\Python313\Lib\site-packages\django\template\base.py", line 883, in _resolve_lookup
    current = current[bit]
              ~~~~~~~^^^^^
TypeError: 'NoneType' object is not subscriptable

During handling of the above exception, another exception occurred:

Traceback (most recent call last):
  File "C:\Users\USER\AppData\Local\Programs\Python\Python313\Lib\site-packages\django\template\base.py", line 893, in _resolve_lookup
    current = getattr(current, bit)
AttributeError: 'NoneType' object has no attribute 'username'

During handling of the above exception, another exception occurred:

Traceback (most recent call last):
  File "C:\Users\USER\AppData\Local\Programs\Python\Python313\Lib\site-packages\django\template\base.py", line 899, in _resolve_lookup
    current = current[int(bit)]
                      ~~~^^^^^
ValueError: invalid literal for int() with base 10: 'username'

During handling of the above exception, another exception occurred:

Traceback (most recent call last):
  File "C:\Users\USER\AppData\Local\Programs\Python\Python313\Lib\site-packages\django\core\handlers\exception.py", line 55, in inner
    response = get_response(request)
  File "C:\Users\USER\AppData\Local\Programs\Python\Python313\Lib\site-packages\django\core\handlers\base.py", line 220, in _get_response
    response = response.render()
  File "C:\Users\USER\AppData\Local\Programs\Python\Python313\Lib\site-packages\django\template\response.py", line 114, in render
    self.content = self.rendered_content
                   ^^^^^^^^^^^^^^^^^^^^^
  File "C:\Users\USER\AppData\Local\Programs\Python\Python313\Lib\site-packages\django\template\response.py", line 92, in rendered_content
    return template.render(context, self._request)
           ~~~~~~~~~~~~~~~^^^^^^^^^^^^^^^^^^^^^^^^
  File "C:\Users\USER\AppData\Local\Programs\Python\Python313\Lib\site-packages\django\template\backends\django.py", line 107, in render
    return self.template.render(context)
           ~~~~~~~~~~~~~~~~~~~~^^^^^^^^^
  File "C:\Users\USER\AppData\Local\Programs\Python\Python313\Lib\site-packages\django\template\base.py", line 171, in render
    return self._render(context)
           ~~~~~~~~~~~~^^^^^^^^^
  File "C:\Users\USER\AppData\Local\Programs\Python\Python313\Lib\site-packages\django\template\base.py", line 163, in _render
    return self.nodelist.render(context)
           ~~~~~~~~~~~~~~~~~~~~^^^^^^^^^
  File "C:\Users\USER\AppData\Local\Programs\Python\Python313\Lib\site-packages\django\template\base.py", line 1008, in render
    return SafeString("".join([node.render_annotated(context) for node in self]))
                               ~~~~~~~~~~~~~~~~~~~~~^^^^^^^^^
  File "C:\Users\USER\AppData\Local\Programs\Python\Python313\Lib\site-packages\django\template\base.py", line 969, in render_annotated
    return self.render(context)
           ~~~~~~~~~~~^^^^^^^^^
  File "C:\Users\USER\AppData\Local\Programs\Python\Python313\Lib\site-packages\django\template\loader_tags.py", line 159, in render
    return compiled_parent._render(context)
           ~~~~~~~~~~~~~~~~~~~~~~~^^^^^^^^^
  File "C:\Users\USER\AppData\Local\Programs\Python\Python313\Lib\site-packages\django\template\base.py", line 163, in _render
    return self.nodelist.render(context)
           ~~~~~~~~~~~~~~~~~~~~^^^^^^^^^
  File "C:\Users\USER\AppData\Local\Programs\Python\Python313\Lib\site-packages\django\template\base.py", line 1008, in render
    return SafeString("".join([node.render_annotated(context) for node in self]))
                               ~~~~~~~~~~~~~~~~~~~~~^^^^^^^^^
  File "C:\Users\USER\AppData\Local\Programs\Python\Python313\Lib\site-packages\django\template\base.py", line 969, in render_annotated
    return self.render(context)
           ~~~~~~~~~~~^^^^^^^^^
  File "C:\Users\USER\AppData\Local\Programs\Python\Python313\Lib\site-packages\django\template\defaulttags.py", line 327, in render
    return nodelist.render(context)
           ~~~~~~~~~~~~~~~^^^^^^^^^
  File "C:\Users\USER\AppData\Local\Programs\Python\Python313\Lib\site-packages\django\template\base.py", line 1008, in render
    return SafeString("".join([node.render_annotated(context) for node in self]))
                               ~~~~~~~~~~~~~~~~~~~~~^^^^^^^^^
  File "C:\Users\USER\AppData\Local\Programs\Python\Python313\Lib\site-packages\django\template\base.py", line 969, in render_annotated
    return self.render(context)
           ~~~~~~~~~~~^^^^^^^^^
  File "C:\Users\USER\AppData\Local\Programs\Python\Python313\Lib\site-packages\django\template\loader_tags.py", line 65, in render
    result = block.nodelist.render(context)
  File "C:\Users\USER\AppData\Local\Programs\Python\Python313\Lib\site-packages\django\template\base.py", line 1008, in render
    return SafeString("".join([node.render_annotated(context) for node in self]))
                               ~~~~~~~~~~~~~~~~~~~~~^^^^^^^^^
  File "C:\Users\USER\AppData\Local\Programs\Python\Python313\Lib\site-packages\django\template\base.py", line 969, in render_annotated
    return self.render(context)
           ~~~~~~~~~~~^^^^^^^^^
  File "C:\Users\USER\AppData\Local\Programs\Python\Python313\Lib\site-packages\django\template\base.py", line 1067, in render
    output = self.filter_expression.resolve(context)
  File "C:\Users\USER\AppData\Local\Programs\Python\Python313\Lib\site-packages\django\template\base.py", line 739, in resolve
    arg_vals.append(arg.resolve(context))
                    ~~~~~~~~~~~^^^^^^^^^
  File "C:\Users\USER\AppData\Local\Programs\Python\Python313\Lib\site-packages\django\template\base.py", line 850, in resolve
    value = self._resolve_lookup(context)
  File "C:\Users\USER\AppData\Local\Programs\Python\Python313\Lib\site-packages\django\template\base.py", line 906, in _resolve_lookup
    raise VariableDoesNotExist(
    ^^^^^^^^^^^^^^^^^^^^^^^^^^^
    ...<2 lines>...
    )  # missing attribute
    ^
django.template.base.VariableDoesNotExist: Failed lookup for key [username] in None
ERROR:django.request:Internal Server Error: /service/234/
Traceback (most recent call last):
  File "C:\Users\USER\AppData\Local\Programs\Python\Python313\Lib\site-packages\django\template\base.py", line 883, in _resolve_lookup
    current = current[bit]
              ~~~~~~~^^^^^
TypeError: 'NoneType' object is not subscriptable

During handling of the above exception, another exception occurred:

Traceback (most recent call last):
  File "C:\Users\USER\AppData\Local\Programs\Python\Python313\Lib\site-packages\django\template\base.py", line 893, in _resolve_lookup
    current = getattr(current, bit)
AttributeError: 'NoneType' object has no attribute 'username'

During handling of the above exception, another exception occurred:

Traceback (most recent call last):
  File "C:\Users\USER\AppData\Local\Programs\Python\Python313\Lib\site-packages\django\template\base.py", line 899, in _resolve_lookup
    current = current[int(bit)]
                      ~~~^^^^^
ValueError: invalid literal for int() with base 10: 'username'

During handling of the above exception, another exception occurred:

Traceback (most recent call last):
  File "C:\Users\USER\AppData\Local\Programs\Python\Python313\Lib\site-packages\django\core\handlers\exception.py", line 55, in inner
    response = get_response(request)
  File "C:\Users\USER\AppData\Local\Programs\Python\Python313\Lib\site-packages\django\core\handlers\base.py", line 220, in _get_response
    response = response.render()
  File "C:\Users\USER\AppData\Local\Programs\Python\Python313\Lib\site-packages\django\template\response.py", line 114, in render
    self.content = self.rendered_content
                   ^^^^^^^^^^^^^^^^^^^^^
  File "C:\Users\USER\AppData\Local\Programs\Python\Python313\Lib\site-packages\django\template\response.py", line 92, in rendered_content
    return template.render(context, self._request)
           ~~~~~~~~~~~~~~~^^^^^^^^^^^^^^^^^^^^^^^^
  File "C:\Users\USER\AppData\Local\Programs\Python\Python313\Lib\site-packages\django\template\backends\django.py", line 107, in render
    return self.template.render(context)
           ~~~~~~~~~~~~~~~~~~~~^^^^^^^^^
  File "C:\Users\USER\AppData\Local\Programs\Python\Python313\Lib\site-packages\django\template\base.py", line 171, in render
    return self._render(context)
           ~~~~~~~~~~~~^^^^^^^^^
  File "C:\Users\USER\AppData\Local\Programs\Python\Python313\Lib\site-packages\django\template\base.py", line 163, in _render
    return self.nodelist.render(context)
           ~~~~~~~~~~~~~~~~~~~~^^^^^^^^^
  File "C:\Users\USER\AppData\Local\Programs\Python\Python313\Lib\site-packages\django\template\base.py", line 1008, in render
    return SafeString("".join([node.render_annotated(context) for node in self]))
                               ~~~~~~~~~~~~~~~~~~~~~^^^^^^^^^
  File "C:\Users\USER\AppData\Local\Programs\Python\Python313\Lib\site-packages\django\template\base.py", line 969, in render_annotated
    return self.render(context)
           ~~~~~~~~~~~^^^^^^^^^
  File "C:\Users\USER\AppData\Local\Programs\Python\Python313\Lib\site-packages\django\template\loader_tags.py", line 159, in render
    return compiled_parent._render(context)
           ~~~~~~~~~~~~~~~~~~~~~~~^^^^^^^^^
  File "C:\Users\USER\AppData\Local\Programs\Python\Python313\Lib\site-packages\django\template\base.py", line 163, in _render
    return self.nodelist.render(context)
           ~~~~~~~~~~~~~~~~~~~~^^^^^^^^^
  File "C:\Users\USER\AppData\Local\Programs\Python\Python313\Lib\site-packages\django\template\base.py", line 1008, in render
    return SafeString("".join([node.render_annotated(context) for node in self]))
                               ~~~~~~~~~~~~~~~~~~~~~^^^^^^^^^
  File "C:\Users\USER\AppData\Local\Programs\Python\Python313\Lib\site-packages\django\template\base.py", line 969, in render_annotated
    return self.render(context)
           ~~~~~~~~~~~^^^^^^^^^
  File "C:\Users\USER\AppData\Local\Programs\Python\Python313\Lib\site-packages\django\template\defaulttags.py", line 327, in render
    return nodelist.render(context)
           ~~~~~~~~~~~~~~~^^^^^^^^^
  File "C:\Users\USER\AppData\Local\Programs\Python\Python313\Lib\site-packages\django\template\base.py", line 1008, in render
    return SafeString("".join([node.render_annotated(context) for node in self]))
                               ~~~~~~~~~~~~~~~~~~~~~^^^^^^^^^
  File "C:\Users\USER\AppData\Local\Programs\Python\Python313\Lib\site-packages\django\template\base.py", line 969, in render_annotated
    return self.render(context)
           ~~~~~~~~~~~^^^^^^^^^
  File "C:\Users\USER\AppData\Local\Programs\Python\Python313\Lib\site-packages\django\template\loader_tags.py", line 65, in render
    result = block.nodelist.render(context)
  File "C:\Users\USER\AppData\Local\Programs\Python\Python313\Lib\site-packages\django\template\base.py", line 1008, in render
    return SafeString("".join([node.render_annotated(context) for node in self]))
                               ~~~~~~~~~~~~~~~~~~~~~^^^^^^^^^
  File "C:\Users\USER\AppData\Local\Programs\Python\Python313\Lib\site-packages\django\template\base.py", line 969, in render_annotated
    return self.render(context)
           ~~~~~~~~~~~^^^^^^^^^
  File "C:\Users\USER\AppData\Local\Programs\Python\Python313\Lib\site-packages\django\template\base.py", line 1067, in render
    output = self.filter_expression.resolve(context)
  File "C:\Users\USER\AppData\Local\Programs\Python\Python313\Lib\site-packages\django\template\base.py", line 739, in resolve
    arg_vals.append(arg.resolve(context))
                    ~~~~~~~~~~~^^^^^^^^^
  File "C:\Users\USER\AppData\Local\Programs\Python\Python313\Lib\site-packages\django\template\base.py", line 850, in resolve
    value = self._resolve_lookup(context)
  File "C:\Users\USER\AppData\Local\Programs\Python\Python313\Lib\site-packages\django\template\base.py", line 906, in _resolve_lookup
    raise VariableDoesNotExist(
    ^^^^^^^^^^^^^^^^^^^^^^^^^^^
    ...<2 lines>...
    )  # missing attribute
    ^
django.template.base.VariableDoesNotExist: Failed lookup for key [username] in None
ERROR:django.request:Internal Server Error: /service/234/
Traceback (most recent call last):
  File "C:\Users\USER\AppData\Local\Programs\Python\Python313\Lib\site-packages\django\template\base.py", line 883, in _resolve_lookup
    current = current[bit]
              ~~~~~~~^^^^^
TypeError: 'NoneType' object is not subscriptable

During handling of the above exception, another exception occurred:

Traceback (most recent call last):
  File "C:\Users\USER\AppData\Local\Programs\Python\Python313\Lib\site-packages\django\template\base.py", line 893, in _resolve_lookup
    current = getattr(current, bit)
AttributeError: 'NoneType' object has no attribute 'username'

During handling of the above exception, another exception occurred:

Traceback (most recent call last):
  File "C:\Users\USER\AppData\Local\Programs\Python\Python313\Lib\site-packages\django\template\base.py", line 899, in _resolve_lookup
    current = current[int(bit)]
                      ~~~^^^^^
ValueError: invalid literal for int() with base 10: 'username'

During handling of the above exception, another exception occurred:

Traceback (most recent call last):
  File "C:\Users\USER\AppData\Local\Programs\Python\Python313\Lib\site-packages\django\core\handlers\exception.py", line 55, in inner
    response = get_response(request)
  File "C:\Users\USER\AppData\Local\Programs\Python\Python313\Lib\site-packages\django\core\handlers\base.py", line 220, in _get_response
    response = response.render()
  File "C:\Users\USER\AppData\Local\Programs\Python\Python313\Lib\site-packages\django\template\response.py", line 114, in render
    self.content = self.rendered_content
                   ^^^^^^^^^^^^^^^^^^^^^
  File "C:\Users\USER\AppData\Local\Programs\Python\Python313\Lib\site-packages\django\template\response.py", line 92, in rendered_content
    return template.render(context, self._request)
           ~~~~~~~~~~~~~~~^^^^^^^^^^^^^^^^^^^^^^^^
  File "C:\Users\USER\AppData\Local\Programs\Python\Python313\Lib\site-packages\django\template\backends\django.py", line 107, in render
    return self.template.render(context)
           ~~~~~~~~~~~~~~~~~~~~^^^^^^^^^
  File "C:\Users\USER\AppData\Local\Programs\Python\Python313\Lib\site-packages\django\template\base.py", line 171, in render
    return self._render(context)
           ~~~~~~~~~~~~^^^^^^^^^
  File "C:\Users\USER\AppData\Local\Programs\Python\Python313\Lib\site-packages\django\template\base.py", line 163, in _render
    return self.nodelist.render(context)
           ~~~~~~~~~~~~~~~~~~~~^^^^^^^^^
  File "C:\Users\USER\AppData\Local\Programs\Python\Python313\Lib\site-packages\django\template\base.py", line 1008, in render
    return SafeString("".join([node.render_annotated(context) for node in self]))
                               ~~~~~~~~~~~~~~~~~~~~~^^^^^^^^^
  File "C:\Users\USER\AppData\Local\Programs\Python\Python313\Lib\site-packages\django\template\base.py", line 969, in render_annotated
    return self.render(context)
           ~~~~~~~~~~~^^^^^^^^^
  File "C:\Users\USER\AppData\Local\Programs\Python\Python313\Lib\site-packages\django\template\loader_tags.py", line 159, in render
    return compiled_parent._render(context)
           ~~~~~~~~~~~~~~~~~~~~~~~^^^^^^^^^
  File "C:\Users\USER\AppData\Local\Programs\Python\Python313\Lib\site-packages\django\template\base.py", line 163, in _render
    return self.nodelist.render(context)
           ~~~~~~~~~~~~~~~~~~~~^^^^^^^^^
  File "C:\Users\USER\AppData\Local\Programs\Python\Python313\Lib\site-packages\django\template\base.py", line 1008, in render
    return SafeString("".join([node.render_annotated(context) for node in self]))
                               ~~~~~~~~~~~~~~~~~~~~~^^^^^^^^^
  File "C:\Users\USER\AppData\Local\Programs\Python\Python313\Lib\site-packages\django\template\base.py", line 969, in render_annotated
    return self.render(context)
           ~~~~~~~~~~~^^^^^^^^^
  File "C:\Users\USER\AppData\Local\Programs\Python\Python313\Lib\site-packages\django\template\defaulttags.py", line 327, in render
    return nodelist.render(context)
           ~~~~~~~~~~~~~~~^^^^^^^^^
  File "C:\Users\USER\AppData\Local\Programs\Python\Python313\Lib\site-packages\django\template\base.py", line 1008, in render
    return SafeString("".join([node.render_annotated(context) for node in self]))
                               ~~~~~~~~~~~~~~~~~~~~~^^^^^^^^^
  File "C:\Users\USER\AppData\Local\Programs\Python\Python313\Lib\site-packages\django\template\base.py", line 969, in render_annotated
    return self.render(context)
           ~~~~~~~~~~~^^^^^^^^^
  File "C:\Users\USER\AppData\Local\Programs\Python\Python313\Lib\site-packages\django\template\loader_tags.py", line 65, in render
    result = block.nodelist.render(context)
  File "C:\Users\USER\AppData\Local\Programs\Python\Python313\Lib\site-packages\django\template\base.py", line 1008, in render
    return SafeString("".join([node.render_annotated(context) for node in self]))
                               ~~~~~~~~~~~~~~~~~~~~~^^^^^^^^^
  File "C:\Users\USER\AppData\Local\Programs\Python\Python313\Lib\site-packages\django\template\base.py", line 969, in render_annotated
    return self.render(context)
           ~~~~~~~~~~~^^^^^^^^^
  File "C:\Users\USER\AppData\Local\Programs\Python\Python313\Lib\site-packages\django\template\base.py", line 1067, in render
    output = self.filter_expression.resolve(context)
  File "C:\Users\USER\AppData\Local\Programs\Python\Python313\Lib\site-packages\django\template\base.py", line 739, in resolve
    arg_vals.append(arg.resolve(context))
                    ~~~~~~~~~~~^^^^^^^^^
  File "C:\Users\USER\AppData\Local\Programs\Python\Python313\Lib\site-packages\django\template\base.py", line 850, in resolve
    value = self._resolve_lookup(context)
  File "C:\Users\USER\AppData\Local\Programs\Python\Python313\Lib\site-packages\django\template\base.py", line 906, in _resolve_lookup
    raise VariableDoesNotExist(
    ^^^^^^^^^^^^^^^^^^^^^^^^^^^
    ...<2 lines>...
    )  # missing attribute
    ^
django.template.base.VariableDoesNotExist: Failed lookup for key [username] in None
ERROR:django.request:Internal Server Error: /service/234/
Traceback (most recent call last):
  File "C:\Users\USER\AppData\Local\Programs\Python\Python313\Lib\site-packages\django\template\base.py", line 883, in _resolve_lookup
    current = current[bit]
              ~~~~~~~^^^^^
TypeError: 'NoneType' object is not subscriptable

During handling of the above exception, another exception occurred:

Traceback (most recent call last):
  File "C:\Users\USER\AppData\Local\Programs\Python\Python313\Lib\site-packages\django\template\base.py", line 893, in _resolve_lookup
    current = getattr(current, bit)
AttributeError: 'NoneType' object has no attribute 'username'

During handling of the above exception, another exception occurred:

Traceback (most recent call last):
  File "C:\Users\USER\AppData\Local\Programs\Python\Python313\Lib\site-packages\django\template\base.py", line 899, in _resolve_lookup
    current = current[int(bit)]
                      ~~~^^^^^
ValueError: invalid literal for int() with base 10: 'username'

During handling of the above exception, another exception occurred:

Traceback (most recent call last):
  File "C:\Users\USER\AppData\Local\Programs\Python\Python313\Lib\site-packages\django\core\handlers\exception.py", line 55, in inner
    response = get_response(request)
  File "C:\Users\USER\AppData\Local\Programs\Python\Python313\Lib\site-packages\django\core\handlers\base.py", line 220, in _get_response
    response = response.render()
  File "C:\Users\USER\AppData\Local\Programs\Python\Python313\Lib\site-packages\django\template\response.py", line 114, in render
    self.content = self.rendered_content
                   ^^^^^^^^^^^^^^^^^^^^^
  File "C:\Users\USER\AppData\Local\Programs\Python\Python313\Lib\site-packages\django\template\response.py", line 92, in rendered_content
    return template.render(context, self._request)
           ~~~~~~~~~~~~~~~^^^^^^^^^^^^^^^^^^^^^^^^
  File "C:\Users\USER\AppData\Local\Programs\Python\Python313\Lib\site-packages\django\template\backends\django.py", line 107, in render
    return self.template.render(context)
           ~~~~~~~~~~~~~~~~~~~~^^^^^^^^^
  File "C:\Users\USER\AppData\Local\Programs\Python\Python313\Lib\site-packages\django\template\base.py", line 171, in render
    return self._render(context)
           ~~~~~~~~~~~~^^^^^^^^^
  File "C:\Users\USER\AppData\Local\Programs\Python\Python313\Lib\site-packages\django\template\base.py", line 163, in _render
    return self.nodelist.render(context)
           ~~~~~~~~~~~~~~~~~~~~^^^^^^^^^
  File "C:\Users\USER\AppData\Local\Programs\Python\Python313\Lib\site-packages\django\template\base.py", line 1008, in render
    return SafeString("".join([node.render_annotated(context) for node in self]))
                               ~~~~~~~~~~~~~~~~~~~~~^^^^^^^^^
  File "C:\Users\USER\AppData\Local\Programs\Python\Python313\Lib\site-packages\django\template\base.py", line 969, in render_annotated
    return self.render(context)
           ~~~~~~~~~~~^^^^^^^^^
  File "C:\Users\USER\AppData\Local\Programs\Python\Python313\Lib\site-packages\django\template\loader_tags.py", line 159, in render
    return compiled_parent._render(context)
           ~~~~~~~~~~~~~~~~~~~~~~~^^^^^^^^^
  File "C:\Users\USER\AppData\Local\Programs\Python\Python313\Lib\site-packages\django\template\base.py", line 163, in _render
    return self.nodelist.render(context)
           ~~~~~~~~~~~~~~~~~~~~^^^^^^^^^
  File "C:\Users\USER\AppData\Local\Programs\Python\Python313\Lib\site-packages\django\template\base.py", line 1008, in render
    return SafeString("".join([node.render_annotated(context) for node in self]))
                               ~~~~~~~~~~~~~~~~~~~~~^^^^^^^^^
  File "C:\Users\USER\AppData\Local\Programs\Python\Python313\Lib\site-packages\django\template\base.py", line 969, in render_annotated
    return self.render(context)
           ~~~~~~~~~~~^^^^^^^^^
  File "C:\Users\USER\AppData\Local\Programs\Python\Python313\Lib\site-packages\django\template\defaulttags.py", line 327, in render
    return nodelist.render(context)
           ~~~~~~~~~~~~~~~^^^^^^^^^
  File "C:\Users\USER\AppData\Local\Programs\Python\Python313\Lib\site-packages\django\template\base.py", line 1008, in render
    return SafeString("".join([node.render_annotated(context) for node in self]))
                               ~~~~~~~~~~~~~~~~~~~~~^^^^^^^^^
  File "C:\Users\USER\AppData\Local\Programs\Python\Python313\Lib\site-packages\django\template\base.py", line 969, in render_annotated
    return self.render(context)
           ~~~~~~~~~~~^^^^^^^^^
  File "C:\Users\USER\AppData\Local\Programs\Python\Python313\Lib\site-packages\django\template\loader_tags.py", line 65, in render
    result = block.nodelist.render(context)
  File "C:\Users\USER\AppData\Local\Programs\Python\Python313\Lib\site-packages\django\template\base.py", line 1008, in render
    return SafeString("".join([node.render_annotated(context) for node in self]))
                               ~~~~~~~~~~~~~~~~~~~~~^^^^^^^^^
  File "C:\Users\USER\AppData\Local\Programs\Python\Python313\Lib\site-packages\django\template\base.py", line 969, in render_annotated
    return self.render(context)
           ~~~~~~~~~~~^^^^^^^^^
  File "C:\Users\USER\AppData\Local\Programs\Python\Python313\Lib\site-packages\django\template\base.py", line 1067, in render
    output = self.filter_expression.resolve(context)
  File "C:\Users\USER\AppData\Local\Programs\Python\Python313\Lib\site-packages\django\template\base.py", line 739, in resolve
    arg_vals.append(arg.resolve(context))
                    ~~~~~~~~~~~^^^^^^^^^
  File "C:\Users\USER\AppData\Local\Programs\Python\Python313\Lib\site-packages\django\template\base.py", line 850, in resolve
    value = self._resolve_lookup(context)
  File "C:\Users\USER\AppData\Local\Programs\Python\Python313\Lib\site-packages\django\template\base.py", line 906, in _resolve_lookup
    raise VariableDoesNotExist(
    ^^^^^^^^^^^^^^^^^^^^^^^^^^^
    ...<2 lines>...
    )  # missing attribute
    ^
django.template.base.VariableDoesNotExist: Failed lookup for key [username] in None
ERROR:django.request:Internal Server Error: /service/234/
Traceback (most recent call last):
  File "C:\Users\USER\AppData\Local\Programs\Python\Python313\Lib\site-packages\django\template\base.py", line 883, in _resolve_lookup
    current = current[bit]
              ~~~~~~~^^^^^
TypeError: 'NoneType' object is not subscriptable

During handling of the above exception, another exception occurred:

Traceback (most recent call last):
  File "C:\Users\USER\AppData\Local\Programs\Python\Python313\Lib\site-packages\django\template\base.py", line 893, in _resolve_lookup
    current = getattr(current, bit)
AttributeError: 'NoneType' object has no attribute 'username'

During handling of the above exception, another exception occurred:

Traceback (most recent call last):
  File "C:\Users\USER\AppData\Local\Programs\Python\Python313\Lib\site-packages\django\template\base.py", line 899, in _resolve_lookup
    current = current[int(bit)]
                      ~~~^^^^^
ValueError: invalid literal for int() with base 10: 'username'

During handling of the above exception, another exception occurred:

Traceback (most recent call last):
  File "C:\Users\USER\AppData\Local\Programs\Python\Python313\Lib\site-packages\django\core\handlers\exception.py", line 55, in inner
    response = get_response(request)
  File "C:\Users\USER\AppData\Local\Programs\Python\Python313\Lib\site-packages\django\core\handlers\base.py", line 220, in _get_response
    response = response.render()
  File "C:\Users\USER\AppData\Local\Programs\Python\Python313\Lib\site-packages\django\template\response.py", line 114, in render
    self.content = self.rendered_content
                   ^^^^^^^^^^^^^^^^^^^^^
  File "C:\Users\USER\AppData\Local\Programs\Python\Python313\Lib\site-packages\django\template\response.py", line 92, in rendered_content
    return template.render(context, self._request)
           ~~~~~~~~~~~~~~~^^^^^^^^^^^^^^^^^^^^^^^^
  File "C:\Users\USER\AppData\Local\Programs\Python\Python313\Lib\site-packages\django\template\backends\django.py", line 107, in render
    return self.template.render(context)
           ~~~~~~~~~~~~~~~~~~~~^^^^^^^^^
  File "C:\Users\USER\AppData\Local\Programs\Python\Python313\Lib\site-packages\django\template\base.py", line 171, in render
    return self._render(context)
           ~~~~~~~~~~~~^^^^^^^^^
  File "C:\Users\USER\AppData\Local\Programs\Python\Python313\Lib\site-packages\django\template\base.py", line 163, in _render
    return self.nodelist.render(context)
           ~~~~~~~~~~~~~~~~~~~~^^^^^^^^^
  File "C:\Users\USER\AppData\Local\Programs\Python\Python313\Lib\site-packages\django\template\base.py", line 1008, in render
    return SafeString("".join([node.render_annotated(context) for node in self]))
                               ~~~~~~~~~~~~~~~~~~~~~^^^^^^^^^
  File "C:\Users\USER\AppData\Local\Programs\Python\Python313\Lib\site-packages\django\template\base.py", line 969, in render_annotated
    return self.render(context)
           ~~~~~~~~~~~^^^^^^^^^
  File "C:\Users\USER\AppData\Local\Programs\Python\Python313\Lib\site-packages\django\template\loader_tags.py", line 159, in render
    return compiled_parent._render(context)
           ~~~~~~~~~~~~~~~~~~~~~~~^^^^^^^^^
  File "C:\Users\USER\AppData\Local\Programs\Python\Python313\Lib\site-packages\django\template\base.py", line 163, in _render
    return self.nodelist.render(context)
           ~~~~~~~~~~~~~~~~~~~~^^^^^^^^^
  File "C:\Users\USER\AppData\Local\Programs\Python\Python313\Lib\site-packages\django\template\base.py", line 1008, in render
    return SafeString("".join([node.render_annotated(context) for node in self]))
                               ~~~~~~~~~~~~~~~~~~~~~^^^^^^^^^
  File "C:\Users\USER\AppData\Local\Programs\Python\Python313\Lib\site-packages\django\template\base.py", line 969, in render_annotated
    return self.render(context)
           ~~~~~~~~~~~^^^^^^^^^
  File "C:\Users\USER\AppData\Local\Programs\Python\Python313\Lib\site-packages\django\template\defaulttags.py", line 327, in render
    return nodelist.render(context)
           ~~~~~~~~~~~~~~~^^^^^^^^^
  File "C:\Users\USER\AppData\Local\Programs\Python\Python313\Lib\site-packages\django\template\base.py", line 1008, in render
    return SafeString("".join([node.render_annotated(context) for node in self]))
                               ~~~~~~~~~~~~~~~~~~~~~^^^^^^^^^
  File "C:\Users\USER\AppData\Local\Programs\Python\Python313\Lib\site-packages\django\template\base.py", line 969, in render_annotated
    return self.render(context)
           ~~~~~~~~~~~^^^^^^^^^
  File "C:\Users\USER\AppData\Local\Programs\Python\Python313\Lib\site-packages\django\template\loader_tags.py", line 65, in render
    result = block.nodelist.render(context)
  File "C:\Users\USER\AppData\Local\Programs\Python\Python313\Lib\site-packages\django\template\base.py", line 1008, in render
    return SafeString("".join([node.render_annotated(context) for node in self]))
                               ~~~~~~~~~~~~~~~~~~~~~^^^^^^^^^
  File "C:\Users\USER\AppData\Local\Programs\Python\Python313\Lib\site-packages\django\template\base.py", line 969, in render_annotated
    return self.render(context)
           ~~~~~~~~~~~^^^^^^^^^
  File "C:\Users\USER\AppData\Local\Programs\Python\Python313\Lib\site-packages\django\template\base.py", line 1067, in render
    output = self.filter_expression.resolve(context)
  File "C:\Users\USER\AppData\Local\Programs\Python\Python313\Lib\site-packages\django\template\base.py", line 739, in resolve
    arg_vals.append(arg.resolve(context))
                    ~~~~~~~~~~~^^^^^^^^^
  File "C:\Users\USER\AppData\Local\Programs\Python\Python313\Lib\site-packages\django\template\base.py", line 850, in resolve
    value = self._resolve_lookup(context)
  File "C:\Users\USER\AppData\Local\Programs\Python\Python313\Lib\site-packages\django\template\base.py", line 906, in _resolve_lookup
    raise VariableDoesNotExist(
    ^^^^^^^^^^^^^^^^^^^^^^^^^^^
    ...<2 lines>...
    )  # missing attribute
    ^
django.template.base.VariableDoesNotExist: Failed lookup for key [username] in None
ERROR:django.request:Internal Server Error: /service/234/
Traceback (most recent call last):
  File "C:\Users\USER\AppData\Local\Programs\Python\Python313\Lib\site-packages\django\template\base.py", line 883, in _resolve_lookup
    current = current[bit]
              ~~~~~~~^^^^^
TypeError: 'NoneType' object is not subscriptable

During handling of the above exception, another exception occurred:

Traceback (most recent call last):
  File "C:\Users\USER\AppData\Local\Programs\Python\Python313\Lib\site-packages\django\template\base.py", line 893, in _resolve_lookup
    current = getattr(current, bit)
AttributeError: 'NoneType' object has no attribute 'username'

During handling of the above exception, another exception occurred:

Traceback (most recent call last):
  File "C:\Users\USER\AppData\Local\Programs\Python\Python313\Lib\site-packages\django\template\base.py", line 899, in _resolve_lookup
    current = current[int(bit)]
                      ~~~^^^^^
ValueError: invalid literal for int() with base 10: 'username'

During handling of the above exception, another exception occurred:

Traceback (most recent call last):
  File "C:\Users\USER\AppData\Local\Programs\Python\Python313\Lib\site-packages\django\core\handlers\exception.py", line 55, in inner
    response = get_response(request)
  File "C:\Users\USER\AppData\Local\Programs\Python\Python313\Lib\site-packages\django\core\handlers\base.py", line 220, in _get_response
    response = response.render()
  File "C:\Users\USER\AppData\Local\Programs\Python\Python313\Lib\site-packages\django\template\response.py", line 114, in render
    self.content = self.rendered_content
                   ^^^^^^^^^^^^^^^^^^^^^
  File "C:\Users\USER\AppData\Local\Programs\Python\Python313\Lib\site-packages\django\template\response.py", line 92, in rendered_content
    return template.render(context, self._request)
           ~~~~~~~~~~~~~~~^^^^^^^^^^^^^^^^^^^^^^^^
  File "C:\Users\USER\AppData\Local\Programs\Python\Python313\Lib\site-packages\django\template\backends\django.py", line 107, in render
    return self.template.render(context)
           ~~~~~~~~~~~~~~~~~~~~^^^^^^^^^
  File "C:\Users\USER\AppData\Local\Programs\Python\Python313\Lib\site-packages\django\template\base.py", line 171, in render
    return self._render(context)
           ~~~~~~~~~~~~^^^^^^^^^
  File "C:\Users\USER\AppData\Local\Programs\Python\Python313\Lib\site-packages\django\template\base.py", line 163, in _render
    return self.nodelist.render(context)
           ~~~~~~~~~~~~~~~~~~~~^^^^^^^^^
  File "C:\Users\USER\AppData\Local\Programs\Python\Python313\Lib\site-packages\django\template\base.py", line 1008, in render
    return SafeString("".join([node.render_annotated(context) for node in self]))
                               ~~~~~~~~~~~~~~~~~~~~~^^^^^^^^^
  File "C:\Users\USER\AppData\Local\Programs\Python\Python313\Lib\site-packages\django\template\base.py", line 969, in render_annotated
    return self.render(context)
           ~~~~~~~~~~~^^^^^^^^^
  File "C:\Users\USER\AppData\Local\Programs\Python\Python313\Lib\site-packages\django\template\loader_tags.py", line 159, in render
    return compiled_parent._render(context)
           ~~~~~~~~~~~~~~~~~~~~~~~^^^^^^^^^
  File "C:\Users\USER\AppData\Local\Programs\Python\Python313\Lib\site-packages\django\template\base.py", line 163, in _render
    return self.nodelist.render(context)
           ~~~~~~~~~~~~~~~~~~~~^^^^^^^^^
  File "C:\Users\USER\AppData\Local\Programs\Python\Python313\Lib\site-packages\django\template\base.py", line 1008, in render
    return SafeString("".join([node.render_annotated(context) for node in self]))
                               ~~~~~~~~~~~~~~~~~~~~~^^^^^^^^^
  File "C:\Users\USER\AppData\Local\Programs\Python\Python313\Lib\site-packages\django\template\base.py", line 969, in render_annotated
    return self.render(context)
           ~~~~~~~~~~~^^^^^^^^^
  File "C:\Users\USER\AppData\Local\Programs\Python\Python313\Lib\site-packages\django\template\defaulttags.py", line 327, in render
    return nodelist.render(context)
           ~~~~~~~~~~~~~~~^^^^^^^^^
  File "C:\Users\USER\AppData\Local\Programs\Python\Python313\Lib\site-packages\django\template\base.py", line 1008, in render
    return SafeString("".join([node.render_annotated(context) for node in self]))
                               ~~~~~~~~~~~~~~~~~~~~~^^^^^^^^^
  File "C:\Users\USER\AppData\Local\Programs\Python\Python313\Lib\site-packages\django\template\base.py", line 969, in render_annotated
    return self.render(context)
           ~~~~~~~~~~~^^^^^^^^^
  File "C:\Users\USER\AppData\Local\Programs\Python\Python313\Lib\site-packages\django\template\loader_tags.py", line 65, in render
    result = block.nodelist.render(context)
  File "C:\Users\USER\AppData\Local\Programs\Python\Python313\Lib\site-packages\django\template\base.py", line 1008, in render
    return SafeString("".join([node.render_annotated(context) for node in self]))
                               ~~~~~~~~~~~~~~~~~~~~~^^^^^^^^^
  File "C:\Users\USER\AppData\Local\Programs\Python\Python313\Lib\site-packages\django\template\base.py", line 969, in render_annotated
    return self.render(context)
           ~~~~~~~~~~~^^^^^^^^^
  File "C:\Users\USER\AppData\Local\Programs\Python\Python313\Lib\site-packages\django\template\base.py", line 1067, in render
    output = self.filter_expression.resolve(context)
  File "C:\Users\USER\AppData\Local\Programs\Python\Python313\Lib\site-packages\django\template\base.py", line 739, in resolve
    arg_vals.append(arg.resolve(context))
                    ~~~~~~~~~~~^^^^^^^^^
  File "C:\Users\USER\AppData\Local\Programs\Python\Python313\Lib\site-packages\django\template\base.py", line 850, in resolve
    value = self._resolve_lookup(context)
  File "C:\Users\USER\AppData\Local\Programs\Python\Python313\Lib\site-packages\django\template\base.py", line 906, in _resolve_lookup
    raise VariableDoesNotExist(
    ^^^^^^^^^^^^^^^^^^^^^^^^^^^
    ...<2 lines>...
    )  # missing attribute
    ^
django.template.base.VariableDoesNotExist: Failed lookup for key [username] in None
ERROR:django.request:Internal Server Error: /service/234/
Traceback (most recent call last):
  File "C:\Users\USER\AppData\Local\Programs\Python\Python313\Lib\site-packages\django\template\base.py", line 883, in _resolve_lookup
    current = current[bit]
              ~~~~~~~^^^^^
TypeError: 'NoneType' object is not subscriptable

During handling of the above exception, another exception occurred:

Traceback (most recent call last):
  File "C:\Users\USER\AppData\Local\Programs\Python\Python313\Lib\site-packages\django\template\base.py", line 893, in _resolve_lookup
    current = getattr(current, bit)
AttributeError: 'NoneType' object has no attribute 'username'

During handling of the above exception, another exception occurred:

Traceback (most recent call last):
  File "C:\Users\USER\AppData\Local\Programs\Python\Python313\Lib\site-packages\django\template\base.py", line 899, in _resolve_lookup
    current = current[int(bit)]
                      ~~~^^^^^
ValueError: invalid literal for int() with base 10: 'username'

During handling of the above exception, another exception occurred:

Traceback (most recent call last):
  File "C:\Users\USER\AppData\Local\Programs\Python\Python313\Lib\site-packages\django\core\handlers\exception.py", line 55, in inner
    response = get_response(request)
  File "C:\Users\USER\AppData\Local\Programs\Python\Python313\Lib\site-packages\django\core\handlers\base.py", line 220, in _get_response
    response = response.render()
  File "C:\Users\USER\AppData\Local\Programs\Python\Python313\Lib\site-packages\django\template\response.py", line 114, in render
    self.content = self.rendered_content
                   ^^^^^^^^^^^^^^^^^^^^^
  File "C:\Users\USER\AppData\Local\Programs\Python\Python313\Lib\site-packages\django\template\response.py", line 92, in rendered_content
    return template.render(context, self._request)
           ~~~~~~~~~~~~~~~^^^^^^^^^^^^^^^^^^^^^^^^
  File "C:\Users\USER\AppData\Local\Programs\Python\Python313\Lib\site-packages\django\template\backends\django.py", line 107, in render
    return self.template.render(context)
           ~~~~~~~~~~~~~~~~~~~~^^^^^^^^^
  File "C:\Users\USER\AppData\Local\Programs\Python\Python313\Lib\site-packages\django\template\base.py", line 171, in render
    return self._render(context)
           ~~~~~~~~~~~~^^^^^^^^^
  File "C:\Users\USER\AppData\Local\Programs\Python\Python313\Lib\site-packages\django\template\base.py", line 163, in _render
    return self.nodelist.render(context)
           ~~~~~~~~~~~~~~~~~~~~^^^^^^^^^
  File "C:\Users\USER\AppData\Local\Programs\Python\Python313\Lib\site-packages\django\template\base.py", line 1008, in render
    return SafeString("".join([node.render_annotated(context) for node in self]))
                               ~~~~~~~~~~~~~~~~~~~~~^^^^^^^^^
  File "C:\Users\USER\AppData\Local\Programs\Python\Python313\Lib\site-packages\django\template\base.py", line 969, in render_annotated
    return self.render(context)
           ~~~~~~~~~~~^^^^^^^^^
  File "C:\Users\USER\AppData\Local\Programs\Python\Python313\Lib\site-packages\django\template\loader_tags.py", line 159, in render
    return compiled_parent._render(context)
           ~~~~~~~~~~~~~~~~~~~~~~~^^^^^^^^^
  File "C:\Users\USER\AppData\Local\Programs\Python\Python313\Lib\site-packages\django\template\base.py", line 163, in _render
    return self.nodelist.render(context)
           ~~~~~~~~~~~~~~~~~~~~^^^^^^^^^
  File "C:\Users\USER\AppData\Local\Programs\Python\Python313\Lib\site-packages\django\template\base.py", line 1008, in render
    return SafeString("".join([node.render_annotated(context) for node in self]))
                               ~~~~~~~~~~~~~~~~~~~~~^^^^^^^^^
  File "C:\Users\USER\AppData\Local\Programs\Python\Python313\Lib\site-packages\django\template\base.py", line 969, in render_annotated
    return self.render(context)
           ~~~~~~~~~~~^^^^^^^^^
  File "C:\Users\USER\AppData\Local\Programs\Python\Python313\Lib\site-packages\django\template\defaulttags.py", line 327, in render
    return nodelist.render(context)
           ~~~~~~~~~~~~~~~^^^^^^^^^
  File "C:\Users\USER\AppData\Local\Programs\Python\Python313\Lib\site-packages\django\template\base.py", line 1008, in render
    return SafeString("".join([node.render_annotated(context) for node in self]))
                               ~~~~~~~~~~~~~~~~~~~~~^^^^^^^^^
  File "C:\Users\USER\AppData\Local\Programs\Python\Python313\Lib\site-packages\django\template\base.py", line 969, in render_annotated
    return self.render(context)
           ~~~~~~~~~~~^^^^^^^^^
  File "C:\Users\USER\AppData\Local\Programs\Python\Python313\Lib\site-packages\django\template\loader_tags.py", line 65, in render
    result = block.nodelist.render(context)
  File "C:\Users\USER\AppData\Local\Programs\Python\Python313\Lib\site-packages\django\template\base.py", line 1008, in render
    return SafeString("".join([node.render_annotated(context) for node in self]))
                               ~~~~~~~~~~~~~~~~~~~~~^^^^^^^^^
  File "C:\Users\USER\AppData\Local\Programs\Python\Python313\Lib\site-packages\django\template\base.py", line 969, in render_annotated
    return self.render(context)
           ~~~~~~~~~~~^^^^^^^^^
  File "C:\Users\USER\AppData\Local\Programs\Python\Python313\Lib\site-packages\django\template\base.py", line 1067, in render
    output = self.filter_expression.resolve(context)
  File "C:\Users\USER\AppData\Local\Programs\Python\Python313\Lib\site-packages\django\template\base.py", line 739, in resolve
    arg_vals.append(arg.resolve(context))
                    ~~~~~~~~~~~^^^^^^^^^
  File "C:\Users\USER\AppData\Local\Programs\Python\Python313\Lib\site-packages\django\template\base.py", line 850, in resolve
    value = self._resolve_lookup(context)
  File "C:\Users\USER\AppData\Local\Programs\Python\Python313\Lib\site-packages\django\template\base.py", line 906, in _resolve_lookup
    raise VariableDoesNotExist(
    ^^^^^^^^^^^^^^^^^^^^^^^^^^^
    ...<2 lines>...
    )  # missing attribute
    ^
django.template.base.VariableDoesNotExist: Failed lookup for key [username] in None
ERROR:django.request:Internal Server Error: /service/234/
Traceback (most recent call last):
  File "C:\Users\USER\AppData\Local\Programs\Python\Python313\Lib\site-packages\django\template\base.py", line 883, in _resolve_lookup
    current = current[bit]
              ~~~~~~~^^^^^
TypeError: 'NoneType' object is not subscriptable

During handling of the above exception, another exception occurred:

Traceback (most recent call last):
  File "C:\Users\USER\AppData\Local\Programs\Python\Python313\Lib\site-packages\django\template\base.py", line 893, in _resolve_lookup
    current = getattr(current, bit)
AttributeError: 'NoneType' object has no attribute 'username'

During handling of the above exception, another exception occurred:

Traceback (most recent call last):
  File "C:\Users\USER\AppData\Local\Programs\Python\Python313\Lib\site-packages\django\template\base.py", line 899, in _resolve_lookup
    current = current[int(bit)]
                      ~~~^^^^^
ValueError: invalid literal for int() with base 10: 'username'

During handling of the above exception, another exception occurred:

Traceback (most recent call last):
  File "C:\Users\USER\AppData\Local\Programs\Python\Python313\Lib\site-packages\django\core\handlers\exception.py", line 55, in inner
    response = get_response(request)
  File "C:\Users\USER\AppData\Local\Programs\Python\Python313\Lib\site-packages\django\core\handlers\base.py", line 220, in _get_response
    response = response.render()
  File "C:\Users\USER\AppData\Local\Programs\Python\Python313\Lib\site-packages\django\template\response.py", line 114, in render
    self.content = self.rendered_content
                   ^^^^^^^^^^^^^^^^^^^^^
  File "C:\Users\USER\AppData\Local\Programs\Python\Python313\Lib\site-packages\django\template\response.py", line 92, in rendered_content
    return template.render(context, self._request)
           ~~~~~~~~~~~~~~~^^^^^^^^^^^^^^^^^^^^^^^^
  File "C:\Users\USER\AppData\Local\Programs\Python\Python313\Lib\site-packages\django\template\backends\django.py", line 107, in render
    return self.template.render(context)
           ~~~~~~~~~~~~~~~~~~~~^^^^^^^^^
  File "C:\Users\USER\AppData\Local\Programs\Python\Python313\Lib\site-packages\django\template\base.py", line 171, in render
    return self._render(context)
           ~~~~~~~~~~~~^^^^^^^^^
  File "C:\Users\USER\AppData\Local\Programs\Python\Python313\Lib\site-packages\django\template\base.py", line 163, in _render
    return self.nodelist.render(context)
           ~~~~~~~~~~~~~~~~~~~~^^^^^^^^^
  File "C:\Users\USER\AppData\Local\Programs\Python\Python313\Lib\site-packages\django\template\base.py", line 1008, in render
    return SafeString("".join([node.render_annotated(context) for node in self]))
                               ~~~~~~~~~~~~~~~~~~~~~^^^^^^^^^
  File "C:\Users\USER\AppData\Local\Programs\Python\Python313\Lib\site-packages\django\template\base.py", line 969, in render_annotated
    return self.render(context)
           ~~~~~~~~~~~^^^^^^^^^
  File "C:\Users\USER\AppData\Local\Programs\Python\Python313\Lib\site-packages\django\template\loader_tags.py", line 159, in render
    return compiled_parent._render(context)
           ~~~~~~~~~~~~~~~~~~~~~~~^^^^^^^^^
  File "C:\Users\USER\AppData\Local\Programs\Python\Python313\Lib\site-packages\django\template\base.py", line 163, in _render
    return self.nodelist.render(context)
           ~~~~~~~~~~~~~~~~~~~~^^^^^^^^^
  File "C:\Users\USER\AppData\Local\Programs\Python\Python313\Lib\site-packages\django\template\base.py", line 1008, in render
    return SafeString("".join([node.render_annotated(context) for node in self]))
                               ~~~~~~~~~~~~~~~~~~~~~^^^^^^^^^
  File "C:\Users\USER\AppData\Local\Programs\Python\Python313\Lib\site-packages\django\template\base.py", line 969, in render_annotated
    return self.render(context)
           ~~~~~~~~~~~^^^^^^^^^
  File "C:\Users\USER\AppData\Local\Programs\Python\Python313\Lib\site-packages\django\template\defaulttags.py", line 327, in render
    return nodelist.render(context)
           ~~~~~~~~~~~~~~~^^^^^^^^^
  File "C:\Users\USER\AppData\Local\Programs\Python\Python313\Lib\site-packages\django\template\base.py", line 1008, in render
    return SafeString("".join([node.render_annotated(context) for node in self]))
                               ~~~~~~~~~~~~~~~~~~~~~^^^^^^^^^
  File "C:\Users\USER\AppData\Local\Programs\Python\Python313\Lib\site-packages\django\template\base.py", line 969, in render_annotated
    return self.render(context)
           ~~~~~~~~~~~^^^^^^^^^
  File "C:\Users\USER\AppData\Local\Programs\Python\Python313\Lib\site-packages\django\template\loader_tags.py", line 65, in render
    result = block.nodelist.render(context)
  File "C:\Users\USER\AppData\Local\Programs\Python\Python313\Lib\site-packages\django\template\base.py", line 1008, in render
    return SafeString("".join([node.render_annotated(context) for node in self]))
                               ~~~~~~~~~~~~~~~~~~~~~^^^^^^^^^
  File "C:\Users\USER\AppData\Local\Programs\Python\Python313\Lib\site-packages\django\template\base.py", line 969, in render_annotated
    return self.render(context)
           ~~~~~~~~~~~^^^^^^^^^
  File "C:\Users\USER\AppData\Local\Programs\Python\Python313\Lib\site-packages\django\template\base.py", line 1067, in render
    output = self.filter_expression.resolve(context)
  File "C:\Users\USER\AppData\Local\Programs\Python\Python313\Lib\site-packages\django\template\base.py", line 739, in resolve
    arg_vals.append(arg.resolve(context))
                    ~~~~~~~~~~~^^^^^^^^^
  File "C:\Users\USER\AppData\Local\Programs\Python\Python313\Lib\site-packages\django\template\base.py", line 850, in resolve
    value = self._resolve_lookup(context)
  File "C:\Users\USER\AppData\Local\Programs\Python\Python313\Lib\site-packages\django\template\base.py", line 906, in _resolve_lookup
    raise VariableDoesNotExist(
    ^^^^^^^^^^^^^^^^^^^^^^^^^^^
    ...<2 lines>...
    )  # missing attribute
    ^
django.template.base.VariableDoesNotExist: Failed lookup for key [username] in None
C:\Users\USER\AppData\Local\Programs\Python\Python313\Lib\site-packages\django\views\generic\list.py:91: UnorderedObjectListWarning: Pagination may yield inconsistent results with an unordered object_list: <class 'customers.models.Customer'> QuerySet.
  return self.paginator_class(
ERROR:django.request:Internal Server Error: /service/234/
Traceback (most recent call last):
  File "C:\Users\USER\AppData\Local\Programs\Python\Python313\Lib\site-packages\django\template\base.py", line 883, in _resolve_lookup
    current = current[bit]
              ~~~~~~~^^^^^
TypeError: 'NoneType' object is not subscriptable

During handling of the above exception, another exception occurred:

Traceback (most recent call last):
  File "C:\Users\USER\AppData\Local\Programs\Python\Python313\Lib\site-packages\django\template\base.py", line 893, in _resolve_lookup
    current = getattr(current, bit)
AttributeError: 'NoneType' object has no attribute 'username'

During handling of the above exception, another exception occurred:

Traceback (most recent call last):
  File "C:\Users\USER\AppData\Local\Programs\Python\Python313\Lib\site-packages\django\template\base.py", line 899, in _resolve_lookup
    current = current[int(bit)]
                      ~~~^^^^^
ValueError: invalid literal for int() with base 10: 'username'

During handling of the above exception, another exception occurred:

Traceback (most recent call last):
  File "C:\Users\USER\AppData\Local\Programs\Python\Python313\Lib\site-packages\django\core\handlers\exception.py", line 55, in inner
    response = get_response(request)
  File "C:\Users\USER\AppData\Local\Programs\Python\Python313\Lib\site-packages\django\core\handlers\base.py", line 220, in _get_response
    response = response.render()
  File "C:\Users\USER\AppData\Local\Programs\Python\Python313\Lib\site-packages\django\template\response.py", line 114, in render
    self.content = self.rendered_content
                   ^^^^^^^^^^^^^^^^^^^^^
  File "C:\Users\USER\AppData\Local\Programs\Python\Python313\Lib\site-packages\django\template\response.py", line 92, in rendered_content
    return template.render(context, self._request)
           ~~~~~~~~~~~~~~~^^^^^^^^^^^^^^^^^^^^^^^^
  File "C:\Users\USER\AppData\Local\Programs\Python\Python313\Lib\site-packages\django\template\backends\django.py", line 107, in render
    return self.template.render(context)
           ~~~~~~~~~~~~~~~~~~~~^^^^^^^^^
  File "C:\Users\USER\AppData\Local\Programs\Python\Python313\Lib\site-packages\django\template\base.py", line 171, in render
    return self._render(context)
           ~~~~~~~~~~~~^^^^^^^^^
  File "C:\Users\USER\AppData\Local\Programs\Python\Python313\Lib\site-packages\django\template\base.py", line 163, in _render
    return self.nodelist.render(context)
           ~~~~~~~~~~~~~~~~~~~~^^^^^^^^^
  File "C:\Users\USER\AppData\Local\Programs\Python\Python313\Lib\site-packages\django\template\base.py", line 1008, in render
    return SafeString("".join([node.render_annotated(context) for node in self]))
                               ~~~~~~~~~~~~~~~~~~~~~^^^^^^^^^
  File "C:\Users\USER\AppData\Local\Programs\Python\Python313\Lib\site-packages\django\template\base.py", line 969, in render_annotated
    return self.render(context)
           ~~~~~~~~~~~^^^^^^^^^
  File "C:\Users\USER\AppData\Local\Programs\Python\Python313\Lib\site-packages\django\template\loader_tags.py", line 159, in render
    return compiled_parent._render(context)
           ~~~~~~~~~~~~~~~~~~~~~~~^^^^^^^^^
  File "C:\Users\USER\AppData\Local\Programs\Python\Python313\Lib\site-packages\django\template\base.py", line 163, in _render
    return self.nodelist.render(context)
           ~~~~~~~~~~~~~~~~~~~~^^^^^^^^^
  File "C:\Users\USER\AppData\Local\Programs\Python\Python313\Lib\site-packages\django\template\base.py", line 1008, in render
    return SafeString("".join([node.render_annotated(context) for node in self]))
                               ~~~~~~~~~~~~~~~~~~~~~^^^^^^^^^
  File "C:\Users\USER\AppData\Local\Programs\Python\Python313\Lib\site-packages\django\template\base.py", line 969, in render_annotated
    return self.render(context)
           ~~~~~~~~~~~^^^^^^^^^
  File "C:\Users\USER\AppData\Local\Programs\Python\Python313\Lib\site-packages\django\template\defaulttags.py", line 327, in render
    return nodelist.render(context)
           ~~~~~~~~~~~~~~~^^^^^^^^^
  File "C:\Users\USER\AppData\Local\Programs\Python\Python313\Lib\site-packages\django\template\base.py", line 1008, in render
    return SafeString("".join([node.render_annotated(context) for node in self]))
                               ~~~~~~~~~~~~~~~~~~~~~^^^^^^^^^
  File "C:\Users\USER\AppData\Local\Programs\Python\Python313\Lib\site-packages\django\template\base.py", line 969, in render_annotated
    return self.render(context)
           ~~~~~~~~~~~^^^^^^^^^
  File "C:\Users\USER\AppData\Local\Programs\Python\Python313\Lib\site-packages\django\template\loader_tags.py", line 65, in render
    result = block.nodelist.render(context)
  File "C:\Users\USER\AppData\Local\Programs\Python\Python313\Lib\site-packages\django\template\base.py", line 1008, in render
    return SafeString("".join([node.render_annotated(context) for node in self]))
                               ~~~~~~~~~~~~~~~~~~~~~^^^^^^^^^
  File "C:\Users\USER\AppData\Local\Programs\Python\Python313\Lib\site-packages\django\template\base.py", line 969, in render_annotated
    return self.render(context)
           ~~~~~~~~~~~^^^^^^^^^
  File "C:\Users\USER\AppData\Local\Programs\Python\Python313\Lib\site-packages\django\template\base.py", line 1067, in render
    output = self.filter_expression.resolve(context)
  File "C:\Users\USER\AppData\Local\Programs\Python\Python313\Lib\site-packages\django\template\base.py", line 739, in resolve
    arg_vals.append(arg.resolve(context))
                    ~~~~~~~~~~~^^^^^^^^^
  File "C:\Users\USER\AppData\Local\Programs\Python\Python313\Lib\site-packages\django\template\base.py", line 850, in resolve
    value = self._resolve_lookup(context)
  File "C:\Users\USER\AppData\Local\Programs\Python\Python313\Lib\site-packages\django\template\base.py", line 906, in _resolve_lookup
    raise VariableDoesNotExist(
    ^^^^^^^^^^^^^^^^^^^^^^^^^^^
    ...<2 lines>...
    )  # missing attribute
    ^
django.template.base.VariableDoesNotExist: Failed lookup for key [username] in None
ERROR:django.request:Internal Server Error: /service/237/
Traceback (most recent call last):
  File "C:\Users\USER\AppData\Local\Programs\Python\Python313\Lib\site-packages\django\template\base.py", line 883, in _resolve_lookup
    current = current[bit]
              ~~~~~~~^^^^^
TypeError: 'NoneType' object is not subscriptable

During handling of the above exception, another exception occurred:

Traceback (most recent call last):
  File "C:\Users\USER\AppData\Local\Programs\Python\Python313\Lib\site-packages\django\template\base.py", line 893, in _resolve_lookup
    current = getattr(current, bit)
AttributeError: 'NoneType' object has no attribute 'username'

During handling of the above exception, another exception occurred:

Traceback (most recent call last):
  File "C:\Users\USER\AppData\Local\Programs\Python\Python313\Lib\site-packages\django\template\base.py", line 899, in _resolve_lookup
    current = current[int(bit)]
                      ~~~^^^^^
ValueError: invalid literal for int() with base 10: 'username'

During handling of the above exception, another exception occurred:

Traceback (most recent call last):
  File "C:\Users\USER\AppData\Local\Programs\Python\Python313\Lib\site-packages\django\core\handlers\exception.py", line 55, in inner
    response = get_response(request)
  File "C:\Users\USER\AppData\Local\Programs\Python\Python313\Lib\site-packages\django\core\handlers\base.py", line 220, in _get_response
    response = response.render()
  File "C:\Users\USER\AppData\Local\Programs\Python\Python313\Lib\site-packages\django\template\response.py", line 114, in render
    self.content = self.rendered_content
                   ^^^^^^^^^^^^^^^^^^^^^
  File "C:\Users\USER\AppData\Local\Programs\Python\Python313\Lib\site-packages\django\template\response.py", line 92, in rendered_content
    return template.render(context, self._request)
           ~~~~~~~~~~~~~~~^^^^^^^^^^^^^^^^^^^^^^^^
  File "C:\Users\USER\AppData\Local\Programs\Python\Python313\Lib\site-packages\django\template\backends\django.py", line 107, in render
    return self.template.render(context)
           ~~~~~~~~~~~~~~~~~~~~^^^^^^^^^
  File "C:\Users\USER\AppData\Local\Programs\Python\Python313\Lib\site-packages\django\template\base.py", line 171, in render
    return self._render(context)
           ~~~~~~~~~~~~^^^^^^^^^
  File "C:\Users\USER\AppData\Local\Programs\Python\Python313\Lib\site-packages\django\template\base.py", line 163, in _render
    return self.nodelist.render(context)
           ~~~~~~~~~~~~~~~~~~~~^^^^^^^^^
  File "C:\Users\USER\AppData\Local\Programs\Python\Python313\Lib\site-packages\django\template\base.py", line 1008, in render
    return SafeString("".join([node.render_annotated(context) for node in self]))
                               ~~~~~~~~~~~~~~~~~~~~~^^^^^^^^^
  File "C:\Users\USER\AppData\Local\Programs\Python\Python313\Lib\site-packages\django\template\base.py", line 969, in render_annotated
    return self.render(context)
           ~~~~~~~~~~~^^^^^^^^^
  File "C:\Users\USER\AppData\Local\Programs\Python\Python313\Lib\site-packages\django\template\loader_tags.py", line 159, in render
    return compiled_parent._render(context)
           ~~~~~~~~~~~~~~~~~~~~~~~^^^^^^^^^
  File "C:\Users\USER\AppData\Local\Programs\Python\Python313\Lib\site-packages\django\template\base.py", line 163, in _render
    return self.nodelist.render(context)
           ~~~~~~~~~~~~~~~~~~~~^^^^^^^^^
  File "C:\Users\USER\AppData\Local\Programs\Python\Python313\Lib\site-packages\django\template\base.py", line 1008, in render
    return SafeString("".join([node.render_annotated(context) for node in self]))
                               ~~~~~~~~~~~~~~~~~~~~~^^^^^^^^^
  File "C:\Users\USER\AppData\Local\Programs\Python\Python313\Lib\site-packages\django\template\base.py", line 969, in render_annotated
    return self.render(context)
           ~~~~~~~~~~~^^^^^^^^^
  File "C:\Users\USER\AppData\Local\Programs\Python\Python313\Lib\site-packages\django\template\defaulttags.py", line 327, in render
    return nodelist.render(context)
           ~~~~~~~~~~~~~~~^^^^^^^^^
  File "C:\Users\USER\AppData\Local\Programs\Python\Python313\Lib\site-packages\django\template\base.py", line 1008, in render
    return SafeString("".join([node.render_annotated(context) for node in self]))
                               ~~~~~~~~~~~~~~~~~~~~~^^^^^^^^^
  File "C:\Users\USER\AppData\Local\Programs\Python\Python313\Lib\site-packages\django\template\base.py", line 969, in render_annotated
    return self.render(context)
           ~~~~~~~~~~~^^^^^^^^^
  File "C:\Users\USER\AppData\Local\Programs\Python\Python313\Lib\site-packages\django\template\loader_tags.py", line 65, in render
    result = block.nodelist.render(context)
  File "C:\Users\USER\AppData\Local\Programs\Python\Python313\Lib\site-packages\django\template\base.py", line 1008, in render
    return SafeString("".join([node.render_annotated(context) for node in self]))
                               ~~~~~~~~~~~~~~~~~~~~~^^^^^^^^^
  File "C:\Users\USER\AppData\Local\Programs\Python\Python313\Lib\site-packages\django\template\base.py", line 969, in render_annotated
    return self.render(context)
           ~~~~~~~~~~~^^^^^^^^^
  File "C:\Users\USER\AppData\Local\Programs\Python\Python313\Lib\site-packages\django\template\base.py", line 1067, in render
    output = self.filter_expression.resolve(context)
  File "C:\Users\USER\AppData\Local\Programs\Python\Python313\Lib\site-packages\django\template\base.py", line 739, in resolve
    arg_vals.append(arg.resolve(context))
                    ~~~~~~~~~~~^^^^^^^^^
  File "C:\Users\USER\AppData\Local\Programs\Python\Python313\Lib\site-packages\django\template\base.py", line 850, in resolve
    value = self._resolve_lookup(context)
  File "C:\Users\USER\AppData\Local\Programs\Python\Python313\Lib\site-packages\django\template\base.py", line 906, in _resolve_lookup
    raise VariableDoesNotExist(
    ^^^^^^^^^^^^^^^^^^^^^^^^^^^
    ...<2 lines>...
    )  # missing attribute
    ^
django.template.base.VariableDoesNotExist: Failed lookup for key [username] in None
ERROR:django.request:Internal Server Error: /service/237/
Traceback (most recent call last):
  File "C:\Users\USER\AppData\Local\Programs\Python\Python313\Lib\site-packages\django\template\base.py", line 883, in _resolve_lookup
    current = current[bit]
              ~~~~~~~^^^^^
TypeError: 'NoneType' object is not subscriptable

During handling of the above exception, another exception occurred:

Traceback (most recent call last):
  File "C:\Users\USER\AppData\Local\Programs\Python\Python313\Lib\site-packages\django\template\base.py", line 893, in _resolve_lookup
    current = getattr(current, bit)
AttributeError: 'NoneType' object has no attribute 'username'

During handling of the above exception, another exception occurred:

Traceback (most recent call last):
  File "C:\Users\USER\AppData\Local\Programs\Python\Python313\Lib\site-packages\django\template\base.py", line 899, in _resolve_lookup
    current = current[int(bit)]
                      ~~~^^^^^
ValueError: invalid literal for int() with base 10: 'username'

During handling of the above exception, another exception occurred:

Traceback (most recent call last):
  File "C:\Users\USER\AppData\Local\Programs\Python\Python313\Lib\site-packages\django\core\handlers\exception.py", line 55, in inner
    response = get_response(request)
  File "C:\Users\USER\AppData\Local\Programs\Python\Python313\Lib\site-packages\django\core\handlers\base.py", line 220, in _get_response
    response = response.render()
  File "C:\Users\USER\AppData\Local\Programs\Python\Python313\Lib\site-packages\django\template\response.py", line 114, in render
    self.content = self.rendered_content
                   ^^^^^^^^^^^^^^^^^^^^^
  File "C:\Users\USER\AppData\Local\Programs\Python\Python313\Lib\site-packages\django\template\response.py", line 92, in rendered_content
    return template.render(context, self._request)
           ~~~~~~~~~~~~~~~^^^^^^^^^^^^^^^^^^^^^^^^
  File "C:\Users\USER\AppData\Local\Programs\Python\Python313\Lib\site-packages\django\template\backends\django.py", line 107, in render
    return self.template.render(context)
           ~~~~~~~~~~~~~~~~~~~~^^^^^^^^^
  File "C:\Users\USER\AppData\Local\Programs\Python\Python313\Lib\site-packages\django\template\base.py", line 171, in render
    return self._render(context)
           ~~~~~~~~~~~~^^^^^^^^^
  File "C:\Users\USER\AppData\Local\Programs\Python\Python313\Lib\site-packages\django\template\base.py", line 163, in _render
    return self.nodelist.render(context)
           ~~~~~~~~~~~~~~~~~~~~^^^^^^^^^
  File "C:\Users\USER\AppData\Local\Programs\Python\Python313\Lib\site-packages\django\template\base.py", line 1008, in render
    return SafeString("".join([node.render_annotated(context) for node in self]))
                               ~~~~~~~~~~~~~~~~~~~~~^^^^^^^^^
  File "C:\Users\USER\AppData\Local\Programs\Python\Python313\Lib\site-packages\django\template\base.py", line 969, in render_annotated
    return self.render(context)
           ~~~~~~~~~~~^^^^^^^^^
  File "C:\Users\USER\AppData\Local\Programs\Python\Python313\Lib\site-packages\django\template\loader_tags.py", line 159, in render
    return compiled_parent._render(context)
           ~~~~~~~~~~~~~~~~~~~~~~~^^^^^^^^^
  File "C:\Users\USER\AppData\Local\Programs\Python\Python313\Lib\site-packages\django\template\base.py", line 163, in _render
    return self.nodelist.render(context)
           ~~~~~~~~~~~~~~~~~~~~^^^^^^^^^
  File "C:\Users\USER\AppData\Local\Programs\Python\Python313\Lib\site-packages\django\template\base.py", line 1008, in render
    return SafeString("".join([node.render_annotated(context) for node in self]))
                               ~~~~~~~~~~~~~~~~~~~~~^^^^^^^^^
  File "C:\Users\USER\AppData\Local\Programs\Python\Python313\Lib\site-packages\django\template\base.py", line 969, in render_annotated
    return self.render(context)
           ~~~~~~~~~~~^^^^^^^^^
  File "C:\Users\USER\AppData\Local\Programs\Python\Python313\Lib\site-packages\django\template\defaulttags.py", line 327, in render
    return nodelist.render(context)
           ~~~~~~~~~~~~~~~^^^^^^^^^
  File "C:\Users\USER\AppData\Local\Programs\Python\Python313\Lib\site-packages\django\template\base.py", line 1008, in render
    return SafeString("".join([node.render_annotated(context) for node in self]))
                               ~~~~~~~~~~~~~~~~~~~~~^^^^^^^^^
  File "C:\Users\USER\AppData\Local\Programs\Python\Python313\Lib\site-packages\django\template\base.py", line 969, in render_annotated
    return self.render(context)
           ~~~~~~~~~~~^^^^^^^^^
  File "C:\Users\USER\AppData\Local\Programs\Python\Python313\Lib\site-packages\django\template\loader_tags.py", line 65, in render
    result = block.nodelist.render(context)
  File "C:\Users\USER\AppData\Local\Programs\Python\Python313\Lib\site-packages\django\template\base.py", line 1008, in render
    return SafeString("".join([node.render_annotated(context) for node in self]))
                               ~~~~~~~~~~~~~~~~~~~~~^^^^^^^^^
  File "C:\Users\USER\AppData\Local\Programs\Python\Python313\Lib\site-packages\django\template\base.py", line 969, in render_annotated
    return self.render(context)
           ~~~~~~~~~~~^^^^^^^^^
  File "C:\Users\USER\AppData\Local\Programs\Python\Python313\Lib\site-packages\django\template\base.py", line 1067, in render
    output = self.filter_expression.resolve(context)
  File "C:\Users\USER\AppData\Local\Programs\Python\Python313\Lib\site-packages\django\template\base.py", line 739, in resolve
    arg_vals.append(arg.resolve(context))
                    ~~~~~~~~~~~^^^^^^^^^
  File "C:\Users\USER\AppData\Local\Programs\Python\Python313\Lib\site-packages\django\template\base.py", line 850, in resolve
    value = self._resolve_lookup(context)
  File "C:\Users\USER\AppData\Local\Programs\Python\Python313\Lib\site-packages\django\template\base.py", line 906, in _resolve_lookup
    raise VariableDoesNotExist(
    ^^^^^^^^^^^^^^^^^^^^^^^^^^^
    ...<2 lines>...
    )  # missing attribute
    ^
django.template.base.VariableDoesNotExist: Failed lookup for key [username] in None
WARNING:waitress.queue:Task queue depth is 1
WARNING:waitress.queue:Task queue depth is 2
WARNING:waitress.queue:Task queue depth is 1
WARNING:waitress.queue:Task queue depth is 1
WARNING:waitress.queue:Task queue depth is 2
WARNING:waitress.queue:Task queue depth is 2
WARNING:waitress.queue:Task queue depth is 1
WARNING:waitress.queue:Task queue depth is 1
WARNING:waitress.queue:Task queue depth is 2
WARNING:waitress.queue:Task queue depth is 1
WARNING:waitress.queue:Task queue depth is 1
WARNING:django.request:Not Found: /favicon.ico
WARNING:django.request:Not Found: /favicon.ico
WARNING:django.request:Not Found: /favicon.ico
INFO:waitress:Serving on http://0.0.0.0:8000
WARNING:django.request:Not Found: /favicon.ico
WARNING:waitress.queue:Task queue depth is 1
WARNING:django.request:Not Found: /favicon.ico
INFO:waitress:Serving on http://0.0.0.0:8000
WARNING:django.request:Not Found: /favicon.ico
WARNING:waitress.queue:Task queue depth is 1
WARNING:django.request:Not Found: /favicon.ico
INFO:waitress:Serving on http://0.0.0.0:8000
WARNING:django.request:Forbidden (Permission denied): /
Traceback (most recent call last):
  File "C:\Users\USER\AppData\Local\Programs\Python\Python313\Lib\site-packages\django\core\handlers\exception.py", line 55, in inner
    response = get_response(request)
  File "C:\Users\USER\AppData\Local\Programs\Python\Python313\Lib\site-packages\django\core\handlers\base.py", line 197, in _get_response
    response = wrapped_callback(request, *callback_args, **callback_kwargs)
  File "C:\Users\USER\AppData\Local\Programs\Python\Python313\Lib\site-packages\django\views\generic\base.py", line 104, in view
    return self.dispatch(request, *args, **kwargs)
           ~~~~~~~~~~~~~^^^^^^^^^^^^^^^^^^^^^^^^^^
  File "C:\Users\USER\AppData\Local\Programs\Python\Python313\Lib\site-packages\django\contrib\auth\mixins.py", line 73, in dispatch
    return super().dispatch(request, *args, **kwargs)
           ~~~~~~~~~~~~~~~~^^^^^^^^^^^^^^^^^^^^^^^^^^
  File "C:\Users\USER\AppData\Local\Programs\Python\Python313\Lib\site-packages\django\contrib\auth\mixins.py", line 134, in dispatch
    return self.handle_no_permission()
           ~~~~~~~~~~~~~~~~~~~~~~~~~^^
  File "C:\Users\USER\AppData\Local\Programs\Python\Python313\Lib\site-packages\django\contrib\auth\mixins.py", line 48, in handle_no_permission
    raise PermissionDenied(self.get_permission_denied_message())
django.core.exceptions.PermissionDenied
WARNING:django.request:Not Found: /favicon.ico
WARNING:django.request:Not Found: /favicon.ico
WARNING:django.request:Not Found: /favicon.ico
WARNING:django.request:Not Found: /favicon.ico
WARNING:django.request:Forbidden (Permission denied): /
Traceback (most recent call last):
  File "C:\Users\USER\AppData\Local\Programs\Python\Python313\Lib\site-packages\django\core\handlers\exception.py", line 55, in inner
    response = get_response(request)
  File "C:\Users\USER\AppData\Local\Programs\Python\Python313\Lib\site-packages\django\core\handlers\base.py", line 197, in _get_response
    response = wrapped_callback(request, *callback_args, **callback_kwargs)
  File "C:\Users\USER\AppData\Local\Programs\Python\Python313\Lib\site-packages\django\views\generic\base.py", line 104, in view
    return self.dispatch(request, *args, **kwargs)
           ~~~~~~~~~~~~~^^^^^^^^^^^^^^^^^^^^^^^^^^
  File "C:\Users\USER\AppData\Local\Programs\Python\Python313\Lib\site-packages\django\contrib\auth\mixins.py", line 73, in dispatch
    return super().dispatch(request, *args, **kwargs)
           ~~~~~~~~~~~~~~~~^^^^^^^^^^^^^^^^^^^^^^^^^^
  File "C:\Users\USER\AppData\Local\Programs\Python\Python313\Lib\site-packages\django\contrib\auth\mixins.py", line 134, in dispatch
    return self.handle_no_permission()
           ~~~~~~~~~~~~~~~~~~~~~~~~~^^
  File "C:\Users\USER\AppData\Local\Programs\Python\Python313\Lib\site-packages\django\contrib\auth\mixins.py", line 48, in handle_no_permission
    raise PermissionDenied(self.get_permission_denied_message())
django.core.exceptions.PermissionDenied
WARNING:django.request:Forbidden (Permission denied): /
Traceback (most recent call last):
  File "C:\Users\USER\AppData\Local\Programs\Python\Python313\Lib\site-packages\django\core\handlers\exception.py", line 55, in inner
    response = get_response(request)
  File "C:\Users\USER\AppData\Local\Programs\Python\Python313\Lib\site-packages\django\core\handlers\base.py", line 197, in _get_response
    response = wrapped_callback(request, *callback_args, **callback_kwargs)
  File "C:\Users\USER\AppData\Local\Programs\Python\Python313\Lib\site-packages\django\views\generic\base.py", line 104, in view
    return self.dispatch(request, *args, **kwargs)
           ~~~~~~~~~~~~~^^^^^^^^^^^^^^^^^^^^^^^^^^
  File "C:\Users\USER\AppData\Local\Programs\Python\Python313\Lib\site-packages\django\contrib\auth\mixins.py", line 73, in dispatch
    return super().dispatch(request, *args, **kwargs)
           ~~~~~~~~~~~~~~~~^^^^^^^^^^^^^^^^^^^^^^^^^^
  File "C:\Users\USER\AppData\Local\Programs\Python\Python313\Lib\site-packages\django\contrib\auth\mixins.py", line 134, in dispatch
    return self.handle_no_permission()
           ~~~~~~~~~~~~~~~~~~~~~~~~~^^
  File "C:\Users\USER\AppData\Local\Programs\Python\Python313\Lib\site-packages\django\contrib\auth\mixins.py", line 48, in handle_no_permission
    raise PermissionDenied(self.get_permission_denied_message())
django.core.exceptions.PermissionDenied
WARNING:waitress.queue:Task queue depth is 1
WARNING:django.request:Not Found: /favicon.ico
WARNING:django.request:Not Found: /favicon.ico
WARNING:django.request:Not Found: /favicon.ico
WARNING:django.request:Not Found: /favicon.ico
WARNING:waitress.queue:Task queue depth is 1
WARNING:waitress.queue:Task queue depth is 2
WARNING:django.request:Forbidden (Permission denied): /
Traceback (most recent call last):
  File "C:\Users\USER\AppData\Local\Programs\Python\Python313\Lib\site-packages\django\core\handlers\exception.py", line 55, in inner
    response = get_response(request)
  File "C:\Users\USER\AppData\Local\Programs\Python\Python313\Lib\site-packages\django\core\handlers\base.py", line 197, in _get_response
    response = wrapped_callback(request, *callback_args, **callback_kwargs)
  File "C:\Users\USER\AppData\Local\Programs\Python\Python313\Lib\site-packages\django\views\generic\base.py", line 104, in view
    return self.dispatch(request, *args, **kwargs)
           ~~~~~~~~~~~~~^^^^^^^^^^^^^^^^^^^^^^^^^^
  File "C:\Users\USER\AppData\Local\Programs\Python\Python313\Lib\site-packages\django\contrib\auth\mixins.py", line 73, in dispatch
    return super().dispatch(request, *args, **kwargs)
           ~~~~~~~~~~~~~~~~^^^^^^^^^^^^^^^^^^^^^^^^^^
  File "C:\Users\USER\AppData\Local\Programs\Python\Python313\Lib\site-packages\django\contrib\auth\mixins.py", line 134, in dispatch
    return self.handle_no_permission()
           ~~~~~~~~~~~~~~~~~~~~~~~~~^^
  File "C:\Users\USER\AppData\Local\Programs\Python\Python313\Lib\site-packages\django\contrib\auth\mixins.py", line 48, in handle_no_permission
    raise PermissionDenied(self.get_permission_denied_message())
django.core.exceptions.PermissionDenied
WARNING:django.request:Not Found: /favicon.ico
INFO:waitress:Serving on http://0.0.0.0:8000
WARNING:django.request:Not Found: /favicon.ico
INFO:waitress:Serving on http://0.0.0.0:8000
WARNING:django.request:Not Found: /favicon.ico
INFO:waitress:Serving on http://0.0.0.0:8000
WARNING:django.request:Not Found: /favicon.ico
ERROR:django.request:Internal Server Error: /service/251/
Traceback (most recent call last):
  File "C:\Users\USER\AppData\Local\Programs\Python\Python313\Lib\site-packages\django\template\base.py", line 883, in _resolve_lookup
    current = current[bit]
              ~~~~~~~^^^^^
TypeError: 'NoneType' object is not subscriptable

During handling of the above exception, another exception occurred:

Traceback (most recent call last):
  File "C:\Users\USER\AppData\Local\Programs\Python\Python313\Lib\site-packages\django\template\base.py", line 893, in _resolve_lookup
    current = getattr(current, bit)
AttributeError: 'NoneType' object has no attribute 'username'

During handling of the above exception, another exception occurred:

Traceback (most recent call last):
  File "C:\Users\USER\AppData\Local\Programs\Python\Python313\Lib\site-packages\django\template\base.py", line 899, in _resolve_lookup
    current = current[int(bit)]
                      ~~~^^^^^
ValueError: invalid literal for int() with base 10: 'username'

During handling of the above exception, another exception occurred:

Traceback (most recent call last):
  File "C:\Users\USER\AppData\Local\Programs\Python\Python313\Lib\site-packages\django\core\handlers\exception.py", line 55, in inner
    response = get_response(request)
  File "C:\Users\USER\AppData\Local\Programs\Python\Python313\Lib\site-packages\django\core\handlers\base.py", line 220, in _get_response
    response = response.render()
  File "C:\Users\USER\AppData\Local\Programs\Python\Python313\Lib\site-packages\django\template\response.py", line 114, in render
    self.content = self.rendered_content
                   ^^^^^^^^^^^^^^^^^^^^^
  File "C:\Users\USER\AppData\Local\Programs\Python\Python313\Lib\site-packages\django\template\response.py", line 92, in rendered_content
    return template.render(context, self._request)
           ~~~~~~~~~~~~~~~^^^^^^^^^^^^^^^^^^^^^^^^
  File "C:\Users\USER\AppData\Local\Programs\Python\Python313\Lib\site-packages\django\template\backends\django.py", line 107, in render
    return self.template.render(context)
           ~~~~~~~~~~~~~~~~~~~~^^^^^^^^^
  File "C:\Users\USER\AppData\Local\Programs\Python\Python313\Lib\site-packages\django\template\base.py", line 171, in render
    return self._render(context)
           ~~~~~~~~~~~~^^^^^^^^^
  File "C:\Users\USER\AppData\Local\Programs\Python\Python313\Lib\site-packages\django\template\base.py", line 163, in _render
    return self.nodelist.render(context)
           ~~~~~~~~~~~~~~~~~~~~^^^^^^^^^
  File "C:\Users\USER\AppData\Local\Programs\Python\Python313\Lib\site-packages\django\template\base.py", line 1008, in render
    return SafeString("".join([node.render_annotated(context) for node in self]))
                               ~~~~~~~~~~~~~~~~~~~~~^^^^^^^^^
  File "C:\Users\USER\AppData\Local\Programs\Python\Python313\Lib\site-packages\django\template\base.py", line 969, in render_annotated
    return self.render(context)
           ~~~~~~~~~~~^^^^^^^^^
  File "C:\Users\USER\AppData\Local\Programs\Python\Python313\Lib\site-packages\django\template\loader_tags.py", line 159, in render
    return compiled_parent._render(context)
           ~~~~~~~~~~~~~~~~~~~~~~~^^^^^^^^^
  File "C:\Users\USER\AppData\Local\Programs\Python\Python313\Lib\site-packages\django\template\base.py", line 163, in _render
    return self.nodelist.render(context)
           ~~~~~~~~~~~~~~~~~~~~^^^^^^^^^
  File "C:\Users\USER\AppData\Local\Programs\Python\Python313\Lib\site-packages\django\template\base.py", line 1008, in render
    return SafeString("".join([node.render_annotated(context) for node in self]))
                               ~~~~~~~~~~~~~~~~~~~~~^^^^^^^^^
  File "C:\Users\USER\AppData\Local\Programs\Python\Python313\Lib\site-packages\django\template\base.py", line 969, in render_annotated
    return self.render(context)
           ~~~~~~~~~~~^^^^^^^^^
  File "C:\Users\USER\AppData\Local\Programs\Python\Python313\Lib\site-packages\django\template\defaulttags.py", line 327, in render
    return nodelist.render(context)
           ~~~~~~~~~~~~~~~^^^^^^^^^
  File "C:\Users\USER\AppData\Local\Programs\Python\Python313\Lib\site-packages\django\template\base.py", line 1008, in render
    return SafeString("".join([node.render_annotated(context) for node in self]))
                               ~~~~~~~~~~~~~~~~~~~~~^^^^^^^^^
  File "C:\Users\USER\AppData\Local\Programs\Python\Python313\Lib\site-packages\django\template\base.py", line 969, in render_annotated
    return self.render(context)
           ~~~~~~~~~~~^^^^^^^^^
  File "C:\Users\USER\AppData\Local\Programs\Python\Python313\Lib\site-packages\django\template\loader_tags.py", line 65, in render
    result = block.nodelist.render(context)
  File "C:\Users\USER\AppData\Local\Programs\Python\Python313\Lib\site-packages\django\template\base.py", line 1008, in render
    return SafeString("".join([node.render_annotated(context) for node in self]))
                               ~~~~~~~~~~~~~~~~~~~~~^^^^^^^^^
  File "C:\Users\USER\AppData\Local\Programs\Python\Python313\Lib\site-packages\django\template\base.py", line 969, in render_annotated
    return self.render(context)
           ~~~~~~~~~~~^^^^^^^^^
  File "C:\Users\USER\AppData\Local\Programs\Python\Python313\Lib\site-packages\django\template\base.py", line 1067, in render
    output = self.filter_expression.resolve(context)
  File "C:\Users\USER\AppData\Local\Programs\Python\Python313\Lib\site-packages\django\template\base.py", line 739, in resolve
    arg_vals.append(arg.resolve(context))
                    ~~~~~~~~~~~^^^^^^^^^
  File "C:\Users\USER\AppData\Local\Programs\Python\Python313\Lib\site-packages\django\template\base.py", line 850, in resolve
    value = self._resolve_lookup(context)
  File "C:\Users\USER\AppData\Local\Programs\Python\Python313\Lib\site-packages\django\template\base.py", line 906, in _resolve_lookup
    raise VariableDoesNotExist(
    ^^^^^^^^^^^^^^^^^^^^^^^^^^^
    ...<2 lines>...
    )  # missing attribute
    ^
django.template.base.VariableDoesNotExist: Failed lookup for key [username] in None
INFO:waitress:Serving on http://0.0.0.0:8000
WARNING:django.request:Not Found: /favicon.ico
